Workbook

Sheet Sheet1
A1: P001168 Rear cover
A2: P001169 Rear locking seats
A3: P001170 Rear lock slider seat
A4: P000159 Equalizer bar hooks
A5: P001171 Left side panel
A6: P001172 Right side plate
A7: P001196 The front corner of the left plate is strengthened
A8: P001287 The front corner of the right plate is strengthened
A9: P001288 Hand handle strengthened
A10: P001173 Mid-mounted disk
A11: P001174 Left cover
A12: P001175 Right cover
... A33: P001187 Drawer back cover

Sheet Sheet2
A1: P001145 Top cover
A2: P001146 Top cover reinforcing plate
A3: P001147 Bottom back
A4: P001148 Large reinforcing plate for the bottom cover
A5: P001167 Small reinforcing plate on the bottom cover
A6: P001149 Box
A7: P001152 Inner backing plate back slot
A8: P001153 Left inner gasket plate front slot
A9: P001154 Right inner pad plate front groove
A10: P001155 Rear locking seats
A11: P001156 Rear lock slider seat
A12: P000159 Equalizer bar hooks
... A23: P001166 Drawer back cover

Sheet CPI27
A1: NO | B1: Status | M1: Remark | N1: PART NAME (Geelong ) | O1: Q'TY | Q1: Work Center | R1: CT | S1: Alt. BOM | T1: Group Center | U1: Seq. | V1: Operation | W1: Group | Y1: 1000 | AB1: 3600
B3: L | C3: 40012178 | N3: TC-2707TSR | O3: 1 | P3: 22.5 | Q3: SCEASA01 | R3: =$AB$1/P3 -> 160 | Y3: =$Y$1/R3 -> 6.25 | AB3: =$Y$1/R3 -> 6.25 | AE3: =$Y$1/R3 -> 6.25 | AH3: =$Y$1/R3 -> 6.25 | AK3: =$Y$1/R3 -> 6.25 | AN3: =$Y$1/R3 -> 6.25
B4: L | D4: 30022112 | N4: U000433 Box Paint | O4: =O3 -> 1 | P4: 22.5 | Q4: SCECOA01 | R4: =$AB$1/P4 -> 160 | Y4: =$Y$1/R4 -> 6.25 | AB4: =$Y$1/R4 -> 6.25 | AE4: =$Y$1/R4 -> 6.25 | AH4: =$Y$1/R4 -> 6.25 | AK4: =$Y$1/R4 -> 6.25 | AN4: =$Y$1/R4 -> 6.25
B5: L | E5: 30022113 | N5: U000433 Box Weld | O5: =O4 -> 1 | P5: =180+60 -> 240 | Q5: SCEGWA01 | R5: =$AB$1/P5 -> 15 | Y5: =$Y$1/R5 -> 66.666667 | AB5: =$Y$1/R5 -> 66.666667 | AE5: =$Y$1/R5 -> 66.666667 | AH5: =$Y$1/R5 -> 66.666667 | AK5: =$Y$1/R5 -> 66.666667 | AN5: =$Y$1/R5 -> 66.666667
B6: L | F6: 30022114 | N6: U000433 Box Spot | O6: =O5 -> 1 | P6: =350 -> 350 | Q6: SCESGA01 | R6: =$AB$1/P6 -> 10.285714 | Y6: =$Y$1/R6 -> 97.222222 | AB6: =$Y$1/R6 -> 97.222222 | AE6: =$Y$1/R6 -> 97.222222 | AH6: =$Y$1/R6 -> 97.222222 | AK6: =$Y$1/R6 -> 97.222222 | AN6: =$Y$1/R6 -> 97.222222
B7: L | G7: 30022115 | N7: P002732 Top Cover Spot | O7: =O6 -> 1 | P7: 10 | Q7: SCESGA01 | R7: =$AB$1/P7 -> 360 | Y7: =$Y$1/R7 -> 2.7777778 | AB7: =$Y$1/R7 -> 2.7777778 | AE7: =$Y$1/R7 -> 2.7777778 | AH7: =$Y$1/R7 -> 2.7777778 | AK7: =$Y$1/R7 -> 2.7777778 | AN7: =$Y$1/R7 -> 2.7777778
B8: L | H8: 30022116 | N8: P002732 Top Cover Bend | O8: =O7 -> 1 | P8: 18 | Q8: SCEBEA02 | R8: =$AB$1/P8 -> 200 | Y8: =$Y$1/R8 -> 5 | AB8: =$Y$1/R8 -> 5 | AE8: =$Y$1/R8 -> 5 | AH8: =$Y$1/R8 -> 5 | AK8: =$Y$1/R8 -> 5 | AN8: =$Y$1/R8 -> 5
B9: L | I9: 30022117 | N9: P002732 Top Cover IPC | O9: =O8 -> 1
B10: L | J10: 10030761 | N10: P002732 Top Cover GP | O10: =O9 -> 1
B11: L | H11: 10030762 | N11: P002571 Hook Holder GP | O11: =O7 -> 1
B12: L | G12: 30022119 | N12: P002733 Bottom Back Bend | O12: =O6 -> 1 | P12: 9 | Q12: SCEBEA02 | R12: =$AB$1/P12 -> 400 | Y12: =$Y$1/R12 -> 2.5 | AB12: =$Y$1/R12 -> 2.5 | AE12: =$Y$1/R12 -> 2.5 | AH12: =$Y$1/R12 -> 2.5 | AK12: =$Y$1/R12 -> 2.5 | AN12: =$Y$1/R12 -> 2.5
B13: L | H13: 30022120 | N13: P002733 Bottom Back IPC | O13: =O12 -> 1
B14: L | I14: 10030763 | N14: P002733 Bottom Back GP | O14: =O13 -> 1
B15: L | G15: 30022121 | N15: P002734 Bottom Cover Reinf Bend | O15: =O6*2 -> 2 | P15: 27 | Q15: SCEBEA02 | R15: =$AB$1/P15 -> 133.33333 | Y15: =$Y$1/R15 -> 7.5 | AB15: =$Y$1/R15 -> 7.5 | AE15: =$Y$1/R15 -> 7.5 | AH15: =$Y$1/R15 -> 7.5 | AK15: =$Y$1/R15 -> 7.5 | AN15: =$Y$1/R15 -> 7.5
B16: L | H16: 10030764 | N16: P002734 Bottom Cover Reinf GP | O16: =O15 -> 2
B17: L | G17: 30023058 | N17: P002951 Box Spot | O17: =O6 -> 1 | P17: =40+40+75+75+45+80 -> 355 | Q17: SCESGA01 | R17: =$AB$1/P17 -> 10.140845 | Y17: =$Y$1/R17 -> 98.611111 | AB17: =$Y$1/R17 -> 98.611111 | AE17: =$Y$1/R17 -> 98.611111 | AH17: =$Y$1/R17 -> 98.611111 | AK17: =$Y$1/R17 -> 98.611111 | AN17: =$Y$1/R17 -> 98.611111
B18: L | H18: 30023056 | N18: P002951 Box Bend | O18: =O17 -> 1 | P18: 54 | Q18: SCESBA01 | R18: =$AB$1/P18 -> 66.666667 | Y18: =$Y$1/R18 -> 15 | AB18: =$Y$1/R18 -> 15 | AE18: =$Y$1/R18 -> 15 | AH18: =$Y$1/R18 -> 15 | AK18: =$Y$1/R18 -> 15 | AN18: =$Y$1/R18 -> 15
B19: L | I19: 30023057 | N19: P002951 Box Press | O19: =O17 -> 1 | P19: 24 | Q19: SCESBA01 | R19: =$AB$1/P19 -> 150 | Y19: =$Y$1/R19 -> 6.6666667 | AB19: =$Y$1/R19 -> 6.6666667 | AE19: =$Y$1/R19 -> 6.6666667 | AH19: =$Y$1/R19 -> 6.6666667 | AK19: =$Y$1/R19 -> 6.6666667 | AN19: =$Y$1/R19 -> 6.6666667
B20: L | J20: 10034385 | N20: P002951 Box GP | O20: =O19 -> 1
B21: L | H21: 30023060 | N21: P002952 BBS Holder Front Left Spot | O21: =O17 -> 1 | P21: 50 | Q21: SCESGA01 | R21: =$AB$1/P21 -> 72 | Y21: =$Y$1/R21 -> 13.888889 | AB21: =$Y$1/R21 -> 13.888889 | AE21: =$Y$1/R21 -> 13.888889 | AH21: =$Y$1/R21 -> 13.888889 | AK21: =$Y$1/R21 -> 13.888889 | AN21: =$Y$1/R21 -> 13.888889
B22: L | I22: 30023059 | N22: P002952 BBS Holder Front Left Press | O22: =O19 -> 1 | P22: 12 | Q22: SCESBA01 | R22: =$AB$1/P22 -> 300 | Y22: =$Y$1/R22 -> 3.3333333 | AB22: =$Y$1/R22 -> 3.3333333 | AE22: =$Y$1/R22 -> 3.3333333 | AH22: =$Y$1/R22 -> 3.3333333 | AK22: =$Y$1/R22 -> 3.3333333 | AN22: =$Y$1/R22 -> 3.3333333
B23: L | J23: 10034386 | N23: P002952 BBS Holder Front Left GP | O23: =O20 -> 1
B24: L | I24: 30023055 | N24: P002801 BBS Holder Front Reinf Bend | O24: =O21 -> 1 | P24: 18 | Q24: SCEBEA02 | R24: =$AB$1/P24 -> 200 | Y24: =$Y$1/R24 -> 5 | AB24: =$Y$1/R24 -> 5 | AE24: =$Y$1/R24 -> 5 | AH24: =$Y$1/R24 -> 5 | AK24: =$Y$1/R24 -> 5 | AN24: =$Y$1/R24 -> 5
B25: L | J25: 30022130 | N25: P002801 BBS Holder Front Reinf Laser | O25: =O24 -> 1 | P25: 13 | Q25: SCECUA04 | R25: =$AB$1/P25 -> 276.92308 | Y25: =$Y$1/R25 -> 3.6111111 | AB25: =$Y$1/R25 -> 3.6111111 | AE25: =$Y$1/R25 -> 3.6111111 | AH25: =$Y$1/R25 -> 3.6111111 | AK25: =$Y$1/R25 -> 3.6111111 | AN25: =$Y$1/R25 -> 3.6111111
B26: L | K26: 10030768 | N26: P002801 BBS Holder Front Reinf GP | O26: =O25 -> 1
B27: L | H27: 30023062 | N27: P002953 BBS Holder Front Right Spot | O27: =O19 -> 1 | P27: 50 | Q27: SCESGA01 | R27: =$AB$1/P27 -> 72 | Y27: =$Y$1/R27 -> 13.888889 | AB27: =$Y$1/R27 -> 13.888889 | AE27: =$Y$1/R27 -> 13.888889 | AH27: =$Y$1/R27 -> 13.888889 | AK27: =$Y$1/R27 -> 13.888889 | AN27: =$Y$1/R27 -> 13.888889
B28: L | I28: 30023061 | N28: P002953 BBS Holder Front Right Press | O28: =O27 -> 1 | P28: 12 | Q28: SCESBA01 | R28: =$AB$1/P28 -> 300 | Y28: =$Y$1/R28 -> 3.3333333 | AB28: =$Y$1/R28 -> 3.3333333 | AE28: =$Y$1/R28 -> 3.3333333 | AH28: =$Y$1/R28 -> 3.3333333 | AK28: =$Y$1/R28 -> 3.3333333 | AN28: =$Y$1/R28 -> 3.3333333
B29: L | J29: 10034387 | N29: P002953 BBS Holder Front Right GP | O29: =O28 -> 1
B30: L | I30: 30023055 | N30: P002801 BBS Holder Front Reinf Bend | O30: =O27 -> 1 | P30: 18 | Q30: SCEBEA02 | R30: =$AB$1/P30 -> 200 | Y30: =$Y$1/R30 -> 5 | AB30: =$Y$1/R30 -> 5 | AE30: =$Y$1/R30 -> 5 | AH30: =$Y$1/R30 -> 5 | AK30: =$Y$1/R30 -> 5 | AN30: =$Y$1/R30 -> 5
B31: L | J31: 30022130 | N31: P002801 BBS Holder Front Reinf Laser | O31: =O30 -> 1 | P31: 13 | Q31: SCECUA04 | R31: =$AB$1/P31 -> 276.92308 | Y31: =$Y$1/R31 -> 3.6111111 | AB31: =$Y$1/R31 -> 3.6111111 | AE31: =$Y$1/R31 -> 3.6111111 | AH31: =$Y$1/R31 -> 3.6111111 | AK31: =$Y$1/R31 -> 3.6111111 | AN31: =$Y$1/R31 -> 3.6111111
B32: L | K32: 10030768 | N32: P002801 BBS Holder Front Reinf GP | O32: =O31 -> 1
B33: L | H33: 30023063 | N33: P002954 BBS Holder Rear Left Press | O33: =O17 -> 1 | P33: 12 | Q33: SCESBA01 | R33: =$AB$1/P33 -> 300 | Y33: =$Y$1/R33 -> 3.3333333 | AB33: =$Y$1/R33 -> 3.3333333 | AE33: =$Y$1/R33 -> 3.3333333 | AH33: =$Y$1/R33 -> 3.3333333 | AK33: =$Y$1/R33 -> 3.3333333 | AN33: =$Y$1/R33 -> 3.3333333
B34: L | I34: 10034388 | N34: P002954 BBS Holder Rear Left GP | O34: =O33 -> 1
B35: L | H35: 30023064 | N35: P002955 BBS Holder Rear Right Press | O35: =O19 -> 1 | P35: 12 | Q35: SCESBA01 | R35: =$AB$1/P35 -> 300 | Y35: =$Y$1/R35 -> 3.3333333 | AB35: =$Y$1/R35 -> 3.3333333 | AE35: =$Y$1/R35 -> 3.3333333 | AH35: =$Y$1/R35 -> 3.3333333 | AK35: =$Y$1/R35 -> 3.3333333 | AN35: =$Y$1/R35 -> 3.3333333
B36: L | I36: 10034389 | N36: P002955 BBS Holder Rear Right GP | O36: =O35 -> 1
B37: L | H37: 30023050 | N37: P002622 Locking Slide Bend | O37: =O17 -> 1 | P37: 36 | Q37: SCEBEA02 | R37: =$AB$1/P37 -> 100 | Y37: =$Y$1/R37 -> 10 | AB37: =$Y$1/R37 -> 10 | AE37: =$Y$1/R37 -> 10 | AH37: =$Y$1/R37 -> 10 | AK37: =$Y$1/R37 -> 10 | AN37: =$Y$1/R37 -> 10
B38: L | I38: 30023145 | N38: P002622 Locking Slide Laser | O38: =O37 -> 1 | P38: 8 | Q38: SCECUA04 | R38: 450 | Y38: 125 | AB38: 125 | AE38: 125 | AH38: 125 | AK38: 125 | AN38: 125
B39: L | J39: 10034294 | N39: P002622 Locking Slide GP | O39: =O37 -> 1
B40: L | H40: 30023053 | N40: P002626 Cover Support Spot | O40: =O17*2 -> 2 | P40: 32 | Q40: SCESGA01 | R40: =$AB$1/P40 -> 112.5 | Y40: =$Y$1/R40 -> 8.8888889 | AB40: =$Y$1/R40 -> 8.8888889 | AE40: =$Y$1/R40 -> 8.8888889 | AH40: =$Y$1/R40 -> 8.8888889 | AK40: =$Y$1/R40 -> 8.8888889 | AN40: =$Y$1/R40 -> 8.8888889
B41: L | I41: 30023051 | N41: P002626 Cover Support Bend | O41: =O40 -> 2 | P41: 18 | Q41: SCEBEA02 | R41: =$AB$1/P41 -> 200 | Y41: =$Y$1/R41 -> 5 | AB41: =$Y$1/R41 -> 5 | AE41: =$Y$1/R41 -> 5 | AH41: =$Y$1/R41 -> 5 | AK41: =$Y$1/R41 -> 5 | AN41: =$Y$1/R41 -> 5
...

Sheet CPI27 (2)
A1: NO | B1: Status | M1: Remark | N1: PART NAME (Geelong ) | O1: Q'TY | Q1: Work Center | R1: CT | S1: Alt. BOM | T1: Group Center | U1: Seq. | V1: Operation | W1: Group | Y1: 1000 | AB1: 3600
B3: L | C3: 40012178 | N3: TC-2707TSR | O3: 1 | P3: 22.5 | Q3: SCEASA01 | R3: =$AB$1/P3 -> 160 | Y3: =$Y$1/R3 -> 6.25 | AB3: =$Y$1/R3 -> 6.25 | AE3: =$Y$1/R3 -> 6.25 | AH3: =$Y$1/R3 -> 6.25 | AK3: =$Y$1/R3 -> 6.25 | AN3: =$Y$1/R3 -> 6.25
B4: L | D4: 30022112 | N4: U000433 Box Paint | O4: =O3 -> 1 | P4: 22.5 | Q4: SCECOA01 | R4: =$AB$1/P4 -> 160 | Y4: =$Y$1/R4 -> 6.25 | AB4: =$Y$1/R4 -> 6.25 | AE4: =$Y$1/R4 -> 6.25 | AH4: =$Y$1/R4 -> 6.25 | AK4: =$Y$1/R4 -> 6.25 | AN4: =$Y$1/R4 -> 6.25
B5: L | E5: 30022113 | N5: U000433 Box Weld | O5: =O4 -> 1 | P5: =180+60 -> 240 | Q5: SCEGWA01 | R5: =$AB$1/P5 -> 15 | Y5: =$Y$1/R5 -> 66.666667 | AB5: =$Y$1/R5 -> 66.666667 | AE5: =$Y$1/R5 -> 66.666667 | AH5: =$Y$1/R5 -> 66.666667 | AK5: =$Y$1/R5 -> 66.666667 | AN5: =$Y$1/R5 -> 66.666667
B6: L | F6: 30022114 | N6: U000433 Box Spot | O6: =O5 -> 1 | P6: =350 -> 350 | Q6: SCESGA01 | R6: =$AB$1/P6 -> 10.285714 | Y6: =$Y$1/R6 -> 97.222222 | AB6: =$Y$1/R6 -> 97.222222 | AE6: =$Y$1/R6 -> 97.222222 | AH6: =$Y$1/R6 -> 97.222222 | AK6: =$Y$1/R6 -> 97.222222 | AN6: =$Y$1/R6 -> 97.222222
B7: L | G7: 30022115 | N7: P002732 Top Cover Spot | O7: =O6 -> 1 | P7: 10 | Q7: SCESGA01 | R7: =$AB$1/P7 -> 360 | Y7: =$Y$1/R7 -> 2.7777778 | AB7: =$Y$1/R7 -> 2.7777778 | AE7: =$Y$1/R7 -> 2.7777778 | AH7: =$Y$1/R7 -> 2.7777778 | AK7: =$Y$1/R7 -> 2.7777778 | AN7: =$Y$1/R7 -> 2.7777778
B8: L | H8: 30022116 | N8: P002732 Top Cover Bend | O8: =O7 -> 1 | P8: 18 | Q8: SCEBEA02 | R8: =$AB$1/P8 -> 200 | Y8: =$Y$1/R8 -> 5 | AB8: =$Y$1/R8 -> 5 | AE8: =$Y$1/R8 -> 5 | AH8: =$Y$1/R8 -> 5 | AK8: =$Y$1/R8 -> 5 | AN8: =$Y$1/R8 -> 5
B9: L | I9: 30022117 | N9: P002732 Top Cover IPC | O9: =O8 -> 1
B10: L | J10: 10030761 | N10: P002732 Top Cover GP | O10: =O9 -> 1
B11: L | H11: 10030762 | N11: P002571 Hook Holder GP | O11: =O7 -> 1
B12: L | G12: 30022119 | N12: P002733 Bottom Back Bend | O12: =O6 -> 1 | P12: 9 | Q12: SCEBEA02 | R12: =$AB$1/P12 -> 400 | Y12: =$Y$1/R12 -> 2.5 | AB12: =$Y$1/R12 -> 2.5 | AE12: =$Y$1/R12 -> 2.5 | AH12: =$Y$1/R12 -> 2.5 | AK12: =$Y$1/R12 -> 2.5 | AN12: =$Y$1/R12 -> 2.5
B13: L | H13: 30022120 | N13: P002733 Bottom Back IPC | O13: =O12 -> 1
B14: L | I14: 10030763 | N14: P002733 Bottom Back GP | O14: =O13 -> 1
B15: L | G15: 30022121 | N15: P002734 Bottom Cover Reinf Bend | O15: =O6*2 -> 2 | P15: 27 | Q15: SCEBEA02 | R15: =$AB$1/P15 -> 133.33333 | Y15: =$Y$1/R15 -> 7.5 | AB15: =$Y$1/R15 -> 7.5 | AE15: =$Y$1/R15 -> 7.5 | AH15: =$Y$1/R15 -> 7.5 | AK15: =$Y$1/R15 -> 7.5 | AN15: =$Y$1/R15 -> 7.5
B16: L | H16: 10030764 | N16: P002734 Bottom Cover Reinf GP | O16: =O15 -> 2
B17: L | G17: 30023058 | N17: P002951 Box Spot | O17: =O6 -> 1 | P17: =40+40+75+75+45+80 -> 355 | Q17: SCESGA01 | R17: =$AB$1/P17 -> 10.140845 | Y17: =$Y$1/R17 -> 98.611111 | AB17: =$Y$1/R17 -> 98.611111 | AE17: =$Y$1/R17 -> 98.611111 | AH17: =$Y$1/R17 -> 98.611111 | AK17: =$Y$1/R17 -> 98.611111 | AN17: =$Y$1/R17 -> 98.611111
B18: L | H18: 30023056 | N18: P002951 Box Bend | O18: =O17 -> 1 | P18: 54 | Q18: SCESBA01 | R18: =$AB$1/P18 -> 66.666667 | Y18: =$Y$1/R18 -> 15 | AB18: =$Y$1/R18 -> 15 | AE18: =$Y$1/R18 -> 15 | AH18: =$Y$1/R18 -> 15 | AK18: =$Y$1/R18 -> 15 | AN18: =$Y$1/R18 -> 15
B19: L | I19: 30023057 | N19: P002951 Box Press | O19: =O17 -> 1 | P19: 24 | Q19: SCESBA01 | R19: =$AB$1/P19 -> 150 | Y19: =$Y$1/R19 -> 6.6666667 | AB19: =$Y$1/R19 -> 6.6666667 | AE19: =$Y$1/R19 -> 6.6666667 | AH19: =$Y$1/R19 -> 6.6666667 | AK19: =$Y$1/R19 -> 6.6666667 | AN19: =$Y$1/R19 -> 6.6666667
B20: L | J20: 10034385 | N20: P002951 Box GP | O20: =O19 -> 1
B21: L | H21: 30023060 | N21: P002952 BBS Holder Front Left Spot | O21: =O17 -> 1 | P21: 50 | Q21: SCESGA01 | R21: =$AB$1/P21 -> 72 | Y21: =$Y$1/R21 -> 13.888889 | AB21: =$Y$1/R21 -> 13.888889 | AE21: =$Y$1/R21 -> 13.888889 | AH21: =$Y$1/R21 -> 13.888889 | AK21: =$Y$1/R21 -> 13.888889 | AN21: =$Y$1/R21 -> 13.888889
B22: L | I22: 30023059 | N22: P002952 BBS Holder Front Left Press | O22: =O19 -> 1 | P22: 12 | Q22: SCESBA01 | R22: =$AB$1/P22 -> 300 | Y22: =$Y$1/R22 -> 3.3333333 | AB22: =$Y$1/R22 -> 3.3333333 | AE22: =$Y$1/R22 -> 3.3333333 | AH22: =$Y$1/R22 -> 3.3333333 | AK22: =$Y$1/R22 -> 3.3333333 | AN22: =$Y$1/R22 -> 3.3333333
B23: L | J23: 10034386 | N23: P002952 BBS Holder Front Left GP | O23: =O20 -> 1
B24: L | I24: 30023055 | N24: P002801 BBS Holder Front Reinf Bend | O24: =O21 -> 1 | P24: 18 | Q24: SCEBEA02 | R24: =$AB$1/P24 -> 200 | Y24: =$Y$1/R24 -> 5 | AB24: =$Y$1/R24 -> 5 | AE24: =$Y$1/R24 -> 5 | AH24: =$Y$1/R24 -> 5 | AK24: =$Y$1/R24 -> 5 | AN24: =$Y$1/R24 -> 5
B25: L | J25: 30022130 | N25: P002801 BBS Holder Front Reinf Laser | O25: =O24 -> 1 | P25: 13 | Q25: SCECUA04 | R25: =$AB$1/P25 -> 276.92308 | Y25: =$Y$1/R25 -> 3.6111111 | AB25: =$Y$1/R25 -> 3.6111111 | AE25: =$Y$1/R25 -> 3.6111111 | AH25: =$Y$1/R25 -> 3.6111111 | AK25: =$Y$1/R25 -> 3.6111111 | AN25: =$Y$1/R25 -> 3.6111111
B26: L | K26: 10030768 | N26: P002801 BBS Holder Front Reinf GP | O26: =O25 -> 1
B27: L | H27: 30023062 | N27: P002953 BBS Holder Front Right Spot | O27: =O19 -> 1 | P27: 50 | Q27: SCESGA01 | R27: =$AB$1/P27 -> 72 | Y27: =$Y$1/R27 -> 13.888889 | AB27: =$Y$1/R27 -> 13.888889 | AE27: =$Y$1/R27 -> 13.888889 | AH27: =$Y$1/R27 -> 13.888889 | AK27: =$Y$1/R27 -> 13.888889 | AN27: =$Y$1/R27 -> 13.888889
B28: L | I28: 30023061 | N28: P002953 BBS Holder Front Right Press | O28: =O27 -> 1 | P28: 12 | Q28: SCESBA01 | R28: =$AB$1/P28 -> 300 | Y28: =$Y$1/R28 -> 3.3333333 | AB28: =$Y$1/R28 -> 3.3333333 | AE28: =$Y$1/R28 -> 3.3333333 | AH28: =$Y$1/R28 -> 3.3333333 | AK28: =$Y$1/R28 -> 3.3333333 | AN28: =$Y$1/R28 -> 3.3333333
B29: L | J29: 10034387 | N29: P002953 BBS Holder Front Right GP | O29: =O28 -> 1
B30: L | I30: 30023055 | N30: P002801 BBS Holder Front Reinf Bend | O30: =O27 -> 1 | P30: 18 | Q30: SCEBEA02 | R30: =$AB$1/P30 -> 200 | Y30: =$Y$1/R30 -> 5 | AB30: =$Y$1/R30 -> 5 | AE30: =$Y$1/R30 -> 5 | AH30: =$Y$1/R30 -> 5 | AK30: =$Y$1/R30 -> 5 | AN30: =$Y$1/R30 -> 5
B31: L | J31: 30022130 | N31: P002801 BBS Holder Front Reinf Laser | O31: =O30 -> 1 | P31: 13 | Q31: SCECUA04 | R31: =$AB$1/P31 -> 276.92308 | Y31: =$Y$1/R31 -> 3.6111111 | AB31: =$Y$1/R31 -> 3.6111111 | AE31: =$Y$1/R31 -> 3.6111111 | AH31: =$Y$1/R31 -> 3.6111111 | AK31: =$Y$1/R31 -> 3.6111111 | AN31: =$Y$1/R31 -> 3.6111111
B32: L | K32: 10030768 | N32: P002801 BBS Holder Front Reinf GP | O32: =O31 -> 1
B33: L | H33: 30023063 | N33: P002954 BBS Holder Rear Left Press | O33: =O17 -> 1 | P33: 12 | Q33: SCESBA01 | R33: =$AB$1/P33 -> 300 | Y33: =$Y$1/R33 -> 3.3333333 | AB33: =$Y$1/R33 -> 3.3333333 | AE33: =$Y$1/R33 -> 3.3333333 | AH33: =$Y$1/R33 -> 3.3333333 | AK33: =$Y$1/R33 -> 3.3333333 | AN33: =$Y$1/R33 -> 3.3333333
B34: L | I34: 10034388 | N34: P002954 BBS Holder Rear Left GP | O34: =O33 -> 1
B35: L | H35: 30023064 | N35: P002955 BBS Holder Rear Right Press | O35: =O19 -> 1 | P35: 12 | Q35: SCESBA01 | R35: =$AB$1/P35 -> 300 | Y35: =$Y$1/R35 -> 3.3333333 | AB35: =$Y$1/R35 -> 3.3333333 | AE35: =$Y$1/R35 -> 3.3333333 | AH35: =$Y$1/R35 -> 3.3333333 | AK35: =$Y$1/R35 -> 3.3333333 | AN35: =$Y$1/R35 -> 3.3333333
B36: L | I36: 10034389 | N36: P002955 BBS Holder Rear Right GP | O36: =O35 -> 1
B37: L | H37: 30023050 | N37: P002622 Locking Slide Bend | O37: =O17 -> 1 | P37: 36 | Q37: SCEBEA02 | R37: =$AB$1/P37 -> 100 | Y37: =$Y$1/R37 -> 10 | AB37: =$Y$1/R37 -> 10 | AE37: =$Y$1/R37 -> 10 | AH37: =$Y$1/R37 -> 10 | AK37: =$Y$1/R37 -> 10 | AN37: =$Y$1/R37 -> 10
B38: L | I38: 30023145 | N38: P002622 Locking Slide Laser | O38: =O37 -> 1 | P38: 8 | Q38: SCECUA04 | R38: 450 | Y38: 125 | AB38: 125 | AE38: 125 | AH38: 125 | AK38: 125 | AN38: 125
B39: L | J39: 10034294 | N39: P002622 Locking Slide GP | O39: =O37 -> 1
B40: L | H40: 30023053 | N40: P002626 Cover Support Spot | O40: =O17*2 -> 2 | P40: 32 | Q40: SCESGA01 | R40: =$AB$1/P40 -> 112.5 | Y40: =$Y$1/R40 -> 8.8888889 | AB40: =$Y$1/R40 -> 8.8888889 | AE40: =$Y$1/R40 -> 8.8888889 | AH40: =$Y$1/R40 -> 8.8888889 | AK40: =$Y$1/R40 -> 8.8888889 | AN40: =$Y$1/R40 -> 8.8888889
B41: L | I41: 30023051 | N41: P002626 Cover Support Bend | O41: =O40 -> 2 | P41: 18 | Q41: SCEBEA02 | R41: =$AB$1/P41 -> 200 | Y41: =$Y$1/R41 -> 5 | AB41: =$Y$1/R41 -> 5 | AE41: =$Y$1/R41 -> 5 | AH41: =$Y$1/R41 -> 5 | AK41: =$Y$1/R41 -> 5 | AN41: =$Y$1/R41 -> 5
...

Sheet CPI27 (3)
A1: NO | B1: Status | M1: Remark | N1: PART NAME (Geelong ) | O1: Q'TY | Q1: Work Center | R1: CT | S1: Alt. BOM | T1: Group Center | U1: Seq. | V1: Operation | W1: Group | Y1: 1000 | AB1: 3600
B3: L | C3: 40012178 | N3: TC-2707TSR | O3: 1 | P3: 22.5 | Q3: SCEASA01 | R3: =$AB$1/P3 -> 160 | Y3: =$Y$1/R3 -> 6.25 | AB3: =$Y$1/R3 -> 6.25 | AE3: =$Y$1/R3 -> 6.25 | AH3: =$Y$1/R3 -> 6.25 | AK3: =$Y$1/R3 -> 6.25 | AN3: =$Y$1/R3 -> 6.25
B4: L | D4: 30022112 | N4: U000433 Box Paint | O4: =O3 -> 1 | P4: 22.5 | Q4: SCECOA01 | R4: =$AB$1/P4 -> 160 | Y4: =$Y$1/R4 -> 6.25 | AB4: =$Y$1/R4 -> 6.25 | AE4: =$Y$1/R4 -> 6.25 | AH4: =$Y$1/R4 -> 6.25 | AK4: =$Y$1/R4 -> 6.25 | AN4: =$Y$1/R4 -> 6.25
B5: L | E5: 30022113 | N5: U000433 Box Weld | O5: =O4 -> 1 | P5: =180+60 -> 240 | Q5: SCEGWA01 | R5: =$AB$1/P5 -> 15 | Y5: =$Y$1/R5 -> 66.666667 | AB5: =$Y$1/R5 -> 66.666667 | AE5: =$Y$1/R5 -> 66.666667 | AH5: =$Y$1/R5 -> 66.666667 | AK5: =$Y$1/R5 -> 66.666667 | AN5: =$Y$1/R5 -> 66.666667
B6: L | F6: 30022114 | N6: U000433 Box Spot | O6: =O5 -> 1 | P6: =350 -> 350 | Q6: SCESGA01 | R6: =$AB$1/P6 -> 10.285714 | Y6: =$Y$1/R6 -> 97.222222 | AB6: =$Y$1/R6 -> 97.222222 | AE6: =$Y$1/R6 -> 97.222222 | AH6: =$Y$1/R6 -> 97.222222 | AK6: =$Y$1/R6 -> 97.222222 | AN6: =$Y$1/R6 -> 97.222222
B7: L | G7: 30022115 | N7: P002732 Top Cover Spot | O7: =O6 -> 1 | P7: 10 | Q7: SCESGA01 | R7: =$AB$1/P7 -> 360 | Y7: =$Y$1/R7 -> 2.7777778 | AB7: =$Y$1/R7 -> 2.7777778 | AE7: =$Y$1/R7 -> 2.7777778 | AH7: =$Y$1/R7 -> 2.7777778 | AK7: =$Y$1/R7 -> 2.7777778 | AN7: =$Y$1/R7 -> 2.7777778
B8: L | H8: 30022116 | N8: P002732 Top Cover Bend | O8: =O7 -> 1 | P8: 18 | Q8: SCEBEA02 | R8: =$AB$1/P8 -> 200 | Y8: =$Y$1/R8 -> 5 | AB8: =$Y$1/R8 -> 5 | AE8: =$Y$1/R8 -> 5 | AH8: =$Y$1/R8 -> 5 | AK8: =$Y$1/R8 -> 5 | AN8: =$Y$1/R8 -> 5
B9: L | I9: 30022117 | N9: P002732 Top Cover IPC | O9: =O8 -> 1
B10: L | J10: 10030761 | N10: P002732 Top Cover GP | O10: =O9 -> 1
B11: L | H11: 10030762 | N11: P002571 Hook Holder GP | O11: =O7 -> 1
B12: L | G12: 30022119 | N12: P002733 Bottom Back Bend | O12: =O6 -> 1 | P12: 9 | Q12: SCEBEA02 | R12: =$AB$1/P12 -> 400 | Y12: =$Y$1/R12 -> 2.5 | AB12: =$Y$1/R12 -> 2.5 | AE12: =$Y$1/R12 -> 2.5 | AH12: =$Y$1/R12 -> 2.5 | AK12: =$Y$1/R12 -> 2.5 | AN12: =$Y$1/R12 -> 2.5
B13: L | H13: 30022120 | N13: P002733 Bottom Back IPC | O13: =O12 -> 1
B14: L | I14: 10030763 | N14: P002733 Bottom Back GP | O14: =O13 -> 1
B15: L | G15: 30022121 | N15: P002734 Bottom Cover Reinf Bend | O15: =O6*2 -> 2 | P15: 27 | Q15: SCEBEA02 | R15: =$AB$1/P15 -> 133.33333 | Y15: =$Y$1/R15 -> 7.5 | AB15: =$Y$1/R15 -> 7.5 | AE15: =$Y$1/R15 -> 7.5 | AH15: =$Y$1/R15 -> 7.5 | AK15: =$Y$1/R15 -> 7.5 | AN15: =$Y$1/R15 -> 7.5
B16: L | H16: 10030764 | N16: P002734 Bottom Cover Reinf GP | O16: =O15 -> 2
B17: L | G17: 30023058 | N17: P002951 Box Spot | O17: =O6 -> 1 | P17: =40+40+75+75+45+80 -> 355 | Q17: SCESGA01 | R17: =$AB$1/P17 -> 10.140845 | Y17: =$Y$1/R17 -> 98.611111 | AB17: =$Y$1/R17 -> 98.611111 | AE17: =$Y$1/R17 -> 98.611111 | AH17: =$Y$1/R17 -> 98.611111 | AK17: =$Y$1/R17 -> 98.611111 | AN17: =$Y$1/R17 -> 98.611111
B18: L | H18: 30023056 | N18: P002951 Box Bend | O18: =O17 -> 1 | P18: 54 | Q18: SCESBA01 | R18: =$AB$1/P18 -> 66.666667 | Y18: =$Y$1/R18 -> 15 | AB18: =$Y$1/R18 -> 15 | AE18: =$Y$1/R18 -> 15 | AH18: =$Y$1/R18 -> 15 | AK18: =$Y$1/R18 -> 15 | AN18: =$Y$1/R18 -> 15
B19: L | I19: 30023057 | N19: P002951 Box Press | O19: =O17 -> 1 | P19: 24 | Q19: SCESBA01 | R19: =$AB$1/P19 -> 150 | Y19: =$Y$1/R19 -> 6.6666667 | AB19: =$Y$1/R19 -> 6.6666667 | AE19: =$Y$1/R19 -> 6.6666667 | AH19: =$Y$1/R19 -> 6.6666667 | AK19: =$Y$1/R19 -> 6.6666667 | AN19: =$Y$1/R19 -> 6.6666667
B20: L | J20: 10034385 | N20: P002951 Box GP | O20: =O19 -> 1
B21: L | H21: 30023060 | N21: P002952 BBS Holder Front Left Spot | O21: =O17 -> 1 | P21: 50 | Q21: SCESGA01 | R21: =$AB$1/P21 -> 72 | Y21: =$Y$1/R21 -> 13.888889 | AB21: =$Y$1/R21 -> 13.888889 | AE21: =$Y$1/R21 -> 13.888889 | AH21: =$Y$1/R21 -> 13.888889 | AK21: =$Y$1/R21 -> 13.888889 | AN21: =$Y$1/R21 -> 13.888889
B22: L | I22: 30023059 | N22: P002952 BBS Holder Front Left Press | O22: =O19 -> 1 | P22: 12 | Q22: SCESBA01 | R22: =$AB$1/P22 -> 300 | Y22: =$Y$1/R22 -> 3.3333333 | AB22: =$Y$1/R22 -> 3.3333333 | AE22: =$Y$1/R22 -> 3.3333333 | AH22: =$Y$1/R22 -> 3.3333333 | AK22: =$Y$1/R22 -> 3.3333333 | AN22: =$Y$1/R22 -> 3.3333333
B23: L | J23: 10034386 | N23: P002952 BBS Holder Front Left GP | O23: =O20 -> 1
B24: L | I24: 30023055 | N24: P002801 BBS Holder Front Reinf Bend | O24: =O21 -> 1 | P24: 18 | Q24: SCEBEA02 | R24: =$AB$1/P24 -> 200 | Y24: =$Y$1/R24 -> 5 | AB24: =$Y$1/R24 -> 5 | AE24: =$Y$1/R24 -> 5 | AH24: =$Y$1/R24 -> 5 | AK24: =$Y$1/R24 -> 5 | AN24: =$Y$1/R24 -> 5
B25: L | J25: 30022130 | N25: P002801 BBS Holder Front Reinf Laser | O25: =O24 -> 1 | P25: 13 | Q25: SCECUA04 | R25: =$AB$1/P25 -> 276.92308 | Y25: =$Y$1/R25 -> 3.6111111 | AB25: =$Y$1/R25 -> 3.6111111 | AE25: =$Y$1/R25 -> 3.6111111 | AH25: =$Y$1/R25 -> 3.6111111 | AK25: =$Y$1/R25 -> 3.6111111 | AN25: =$Y$1/R25 -> 3.6111111
B26: L | K26: 10030768 | N26: P002801 BBS Holder Front Reinf GP | O26: =O25 -> 1
B27: L | H27: 30023062 | N27: P002953 BBS Holder Front Right Spot | O27: =O19 -> 1 | P27: 50 | Q27: SCESGA01 | R27: =$AB$1/P27 -> 72 | Y27: =$Y$1/R27 -> 13.888889 | AB27: =$Y$1/R27 -> 13.888889 | AE27: =$Y$1/R27 -> 13.888889 | AH27: =$Y$1/R27 -> 13.888889 | AK27: =$Y$1/R27 -> 13.888889 | AN27: =$Y$1/R27 -> 13.888889
B28: L | I28: 30023061 | N28: P002953 BBS Holder Front Right Press | O28: =O27 -> 1 | P28: 12 | Q28: SCESBA01 | R28: =$AB$1/P28 -> 300 | Y28: =$Y$1/R28 -> 3.3333333 | AB28: =$Y$1/R28 -> 3.3333333 | AE28: =$Y$1/R28 -> 3.3333333 | AH28: =$Y$1/R28 -> 3.3333333 | AK28: =$Y$1/R28 -> 3.3333333 | AN28: =$Y$1/R28 -> 3.3333333
B29: L | J29: 10034387 | N29: P002953 BBS Holder Front Right GP | O29: =O28 -> 1
B30: L | I30: 30023055 | N30: P002801 BBS Holder Front Reinf Bend | O30: =O27 -> 1 | P30: 18 | Q30: SCEBEA02 | R30: =$AB$1/P30 -> 200 | Y30: =$Y$1/R30 -> 5 | AB30: =$Y$1/R30 -> 5 | AE30: =$Y$1/R30 -> 5 | AH30: =$Y$1/R30 -> 5 | AK30: =$Y$1/R30 -> 5 | AN30: =$Y$1/R30 -> 5
B31: L | J31: 30022130 | N31: P002801 BBS Holder Front Reinf Laser | O31: =O30 -> 1 | P31: 13 | Q31: SCECUA04 | R31: =$AB$1/P31 -> 276.92308 | Y31: =$Y$1/R31 -> 3.6111111 | AB31: =$Y$1/R31 -> 3.6111111 | AE31: =$Y$1/R31 -> 3.6111111 | AH31: =$Y$1/R31 -> 3.6111111 | AK31: =$Y$1/R31 -> 3.6111111 | AN31: =$Y$1/R31 -> 3.6111111
B32: L | K32: 10030768 | N32: P002801 BBS Holder Front Reinf GP | O32: =O31 -> 1
B33: L | H33: 30023063 | N33: P002954 BBS Holder Rear Left Press | O33: =O17 -> 1 | P33: 12 | Q33: SCESBA01 | R33: =$AB$1/P33 -> 300 | Y33: =$Y$1/R33 -> 3.3333333 | AB33: =$Y$1/R33 -> 3.3333333 | AE33: =$Y$1/R33 -> 3.3333333 | AH33: =$Y$1/R33 -> 3.3333333 | AK33: =$Y$1/R33 -> 3.3333333 | AN33: =$Y$1/R33 -> 3.3333333
B34: L | I34: 10034388 | N34: P002954 BBS Holder Rear Left GP | O34: =O33 -> 1
B35: L | H35: 30023064 | N35: P002955 BBS Holder Rear Right Press | O35: =O19 -> 1 | P35: 12 | Q35: SCESBA01 | R35: =$AB$1/P35 -> 300 | Y35: =$Y$1/R35 -> 3.3333333 | AB35: =$Y$1/R35 -> 3.3333333 | AE35: =$Y$1/R35 -> 3.3333333 | AH35: =$Y$1/R35 -> 3.3333333 | AK35: =$Y$1/R35 -> 3.3333333 | AN35: =$Y$1/R35 -> 3.3333333
B36: L | I36: 10034389 | N36: P002955 BBS Holder Rear Right GP | O36: =O35 -> 1
B37: L | H37: 30023050 | N37: P002622 Locking Slide Bend | O37: =O17 -> 1 | P37: 36 | Q37: SCEBEA02 | R37: =$AB$1/P37 -> 100 | Y37: =$Y$1/R37 -> 10 | AB37: =$Y$1/R37 -> 10 | AE37: =$Y$1/R37 -> 10 | AH37: =$Y$1/R37 -> 10 | AK37: =$Y$1/R37 -> 10 | AN37: =$Y$1/R37 -> 10
B38: L | I38: 30023145 | N38: P002622 Locking Slide Laser | O38: =O37 -> 1 | P38: 8 | Q38: SCECUA04 | R38: 450 | Y38: 125 | AB38: 125 | AE38: 125 | AH38: 125 | AK38: 125 | AN38: 125
B39: L | J39: 10034294 | N39: P002622 Locking Slide GP | O39: =O37 -> 1
B40: L | H40: 30023053 | N40: P002626 Cover Support Spot | O40: =O17*2 -> 2 | P40: 32 | Q40: SCESGA01 | R40: =$AB$1/P40 -> 112.5 | Y40: =$Y$1/R40 -> 8.8888889 | AB40: =$Y$1/R40 -> 8.8888889 | AE40: =$Y$1/R40 -> 8.8888889 | AH40: =$Y$1/R40 -> 8.8888889 | AK40: =$Y$1/R40 -> 8.8888889 | AN40: =$Y$1/R40 -> 8.8888889
B41: L | I41: 30023051 | N41: P002626 Cover Support Bend | O41: =O40 -> 2 | P41: 18 | Q41: SCEBEA02 | R41: =$AB$1/P41 -> 200 | Y41: =$Y$1/R41 -> 5 | AB41: =$Y$1/R41 -> 5 | AE41: =$Y$1/R41 -> 5 | AH41: =$Y$1/R41 -> 5 | AK41: =$Y$1/R41 -> 5 | AN41: =$Y$1/R41 -> 5
...

Sheet CPI27 (4)
A1: NO | B1: Status | M1: Remark | N1: PART NAME (Geelong ) | O1: Q'TY | Q1: Work Center | R1: CT | S1: Alt. BOM | T1: Group Center | U1: Seq. | V1: Operation | W1: Group | Y1: 1000 | AB1: 3600
B3: L | C3: 40012178 | N3: TC-2707TSR | O3: 1 | P3: 22.5 | Q3: SCEASA01 | R3: =$AB$1/P3 -> 160 | Y3: =$Y$1/R3 -> 6.25 | AB3: =$Y$1/R3 -> 6.25 | AE3: =$Y$1/R3 -> 6.25 | AH3: =$Y$1/R3 -> 6.25 | AK3: =$Y$1/R3 -> 6.25 | AN3: =$Y$1/R3 -> 6.25
B4: L | D4: 30022112 | N4: U000433 Box Paint | O4: =O3 -> 1 | P4: 22.5 | Q4: SCECOA01 | R4: =$AB$1/P4 -> 160 | Y4: =$Y$1/R4 -> 6.25 | AB4: =$Y$1/R4 -> 6.25 | AE4: =$Y$1/R4 -> 6.25 | AH4: =$Y$1/R4 -> 6.25 | AK4: =$Y$1/R4 -> 6.25 | AN4: =$Y$1/R4 -> 6.25
B5: L | E5: 30022113 | N5: U000433 Box Weld | O5: =O4 -> 1 | P5: =180+60 -> 240 | Q5: SCEGWA01 | R5: =$AB$1/P5 -> 15 | Y5: =$Y$1/R5 -> 66.666667 | AB5: =$Y$1/R5 -> 66.666667 | AE5: =$Y$1/R5 -> 66.666667 | AH5: =$Y$1/R5 -> 66.666667 | AK5: =$Y$1/R5 -> 66.666667 | AN5: =$Y$1/R5 -> 66.666667
B6: L | F6: 30022114 | N6: U000433 Box Spot | O6: =O5 -> 1 | P6: =350 -> 350 | Q6: SCESGA01 | R6: =$AB$1/P6 -> 10.285714 | Y6: =$Y$1/R6 -> 97.222222 | AB6: =$Y$1/R6 -> 97.222222 | AE6: =$Y$1/R6 -> 97.222222 | AH6: =$Y$1/R6 -> 97.222222 | AK6: =$Y$1/R6 -> 97.222222 | AN6: =$Y$1/R6 -> 97.222222
B7: L | G7: 30022115 | N7: P002732 Top Cover Spot | O7: =O6 -> 1 | P7: 10 | Q7: SCESGA01 | R7: =$AB$1/P7 -> 360 | Y7: =$Y$1/R7 -> 2.7777778 | AB7: =$Y$1/R7 -> 2.7777778 | AE7: =$Y$1/R7 -> 2.7777778 | AH7: =$Y$1/R7 -> 2.7777778 | AK7: =$Y$1/R7 -> 2.7777778 | AN7: =$Y$1/R7 -> 2.7777778
B8: L | H8: 30022116 | N8: P002732 Top Cover Bend | O8: =O7 -> 1 | P8: 18 | Q8: SCEBEA02 | R8: =$AB$1/P8 -> 200 | Y8: =$Y$1/R8 -> 5 | AB8: =$Y$1/R8 -> 5 | AE8: =$Y$1/R8 -> 5 | AH8: =$Y$1/R8 -> 5 | AK8: =$Y$1/R8 -> 5 | AN8: =$Y$1/R8 -> 5
B9: L | I9: 30022117 | N9: P002732 Top Cover IPC | O9: =O8 -> 1
B10: L | J10: 10030761 | N10: P002732 Top Cover GP | O10: =O9 -> 1
B11: L | H11: 10030762 | N11: P002571 Hook Holder GP | O11: =O7 -> 1
B12: L | G12: 30022119 | N12: P002733 Bottom Back Bend | O12: =O6 -> 1 | P12: 9 | Q12: SCEBEA02 | R12: =$AB$1/P12 -> 400 | Y12: =$Y$1/R12 -> 2.5 | AB12: =$Y$1/R12 -> 2.5 | AE12: =$Y$1/R12 -> 2.5 | AH12: =$Y$1/R12 -> 2.5 | AK12: =$Y$1/R12 -> 2.5 | AN12: =$Y$1/R12 -> 2.5
B13: L | H13: 30022120 | N13: P002733 Bottom Back IPC | O13: =O12 -> 1
B14: L | I14: 10030763 | N14: P002733 Bottom Back GP | O14: =O13 -> 1
B15: L | G15: 30022121 | N15: P002734 Bottom Cover Reinf Bend | O15: =O6*2 -> 2 | P15: 27 | Q15: SCEBEA02 | R15: =$AB$1/P15 -> 133.33333 | Y15: =$Y$1/R15 -> 7.5 | AB15: =$Y$1/R15 -> 7.5 | AE15: =$Y$1/R15 -> 7.5 | AH15: =$Y$1/R15 -> 7.5 | AK15: =$Y$1/R15 -> 7.5 | AN15: =$Y$1/R15 -> 7.5
B16: L | H16: 10030764 | N16: P002734 Bottom Cover Reinf GP | O16: =O15 -> 2
B17: L | G17: 30023058 | N17: P002951 Box Spot | O17: =O6 -> 1 | P17: =40+40+75+75+45+80 -> 355 | Q17: SCESGA01 | R17: =$AB$1/P17 -> 10.140845 | Y17: =$Y$1/R17 -> 98.611111 | AB17: =$Y$1/R17 -> 98.611111 | AE17: =$Y$1/R17 -> 98.611111 | AH17: =$Y$1/R17 -> 98.611111 | AK17: =$Y$1/R17 -> 98.611111 | AN17: =$Y$1/R17 -> 98.611111
B18: L | H18: 30023056 | N18: P002951 Box Bend | O18: =O17 -> 1 | P18: 54 | Q18: SCESBA01 | R18: =$AB$1/P18 -> 66.666667 | Y18: =$Y$1/R18 -> 15 | AB18: =$Y$1/R18 -> 15 | AE18: =$Y$1/R18 -> 15 | AH18: =$Y$1/R18 -> 15 | AK18: =$Y$1/R18 -> 15 | AN18: =$Y$1/R18 -> 15
B19: L | I19: 30023057 | N19: P002951 Box Press | O19: =O17 -> 1 | P19: 24 | Q19: SCESBA01 | R19: =$AB$1/P19 -> 150 | Y19: =$Y$1/R19 -> 6.6666667 | AB19: =$Y$1/R19 -> 6.6666667 | AE19: =$Y$1/R19 -> 6.6666667 | AH19: =$Y$1/R19 -> 6.6666667 | AK19: =$Y$1/R19 -> 6.6666667 | AN19: =$Y$1/R19 -> 6.6666667
B20: L | J20: 10034385 | N20: P002951 Box GP | O20: =O19 -> 1
B21: L | H21: 30023060 | N21: P002952 BBS Holder Front Left Spot | O21: =O17 -> 1 | P21: 50 | Q21: SCESGA01 | R21: =$AB$1/P21 -> 72 | Y21: =$Y$1/R21 -> 13.888889 | AB21: =$Y$1/R21 -> 13.888889 | AE21: =$Y$1/R21 -> 13.888889 | AH21: =$Y$1/R21 -> 13.888889 | AK21: =$Y$1/R21 -> 13.888889 | AN21: =$Y$1/R21 -> 13.888889
B22: L | I22: 30023059 | N22: P002952 BBS Holder Front Left Press | O22: =O19 -> 1 | P22: 12 | Q22: SCESBA01 | R22: =$AB$1/P22 -> 300 | Y22: =$Y$1/R22 -> 3.3333333 | AB22: =$Y$1/R22 -> 3.3333333 | AE22: =$Y$1/R22 -> 3.3333333 | AH22: =$Y$1/R22 -> 3.3333333 | AK22: =$Y$1/R22 -> 3.3333333 | AN22: =$Y$1/R22 -> 3.3333333
B23: L | J23: 10034386 | N23: P002952 BBS Holder Front Left GP | O23: =O20 -> 1
B24: L | I24: 30023055 | N24: P002801 BBS Holder Front Reinf Bend | O24: =O21 -> 1 | P24: 18 | Q24: SCEBEA02 | R24: =$AB$1/P24 -> 200 | Y24: =$Y$1/R24 -> 5 | AB24: =$Y$1/R24 -> 5 | AE24: =$Y$1/R24 -> 5 | AH24: =$Y$1/R24 -> 5 | AK24: =$Y$1/R24 -> 5 | AN24: =$Y$1/R24 -> 5
B25: L | J25: 30022130 | N25: P002801 BBS Holder Front Reinf Laser | O25: =O24 -> 1 | P25: 13 | Q25: SCECUA04 | R25: =$AB$1/P25 -> 276.92308 | Y25: =$Y$1/R25 -> 3.6111111 | AB25: =$Y$1/R25 -> 3.6111111 | AE25: =$Y$1/R25 -> 3.6111111 | AH25: =$Y$1/R25 -> 3.6111111 | AK25: =$Y$1/R25 -> 3.6111111 | AN25: =$Y$1/R25 -> 3.6111111
B26: L | K26: 10030768 | N26: P002801 BBS Holder Front Reinf GP | O26: =O25 -> 1
B27: L | H27: 30023062 | N27: P002953 BBS Holder Front Right Spot | O27: =O19 -> 1 | P27: 50 | Q27: SCESGA01 | R27: =$AB$1/P27 -> 72 | Y27: =$Y$1/R27 -> 13.888889 | AB27: =$Y$1/R27 -> 13.888889 | AE27: =$Y$1/R27 -> 13.888889 | AH27: =$Y$1/R27 -> 13.888889 | AK27: =$Y$1/R27 -> 13.888889 | AN27: =$Y$1/R27 -> 13.888889
B28: L | I28: 30023061 | N28: P002953 BBS Holder Front Right Press | O28: =O27 -> 1 | P28: 12 | Q28: SCESBA01 | R28: =$AB$1/P28 -> 300 | Y28: =$Y$1/R28 -> 3.3333333 | AB28: =$Y$1/R28 -> 3.3333333 | AE28: =$Y$1/R28 -> 3.3333333 | AH28: =$Y$1/R28 -> 3.3333333 | AK28: =$Y$1/R28 -> 3.3333333 | AN28: =$Y$1/R28 -> 3.3333333
B29: L | J29: 10034387 | N29: P002953 BBS Holder Front Right GP | O29: =O28 -> 1
B30: L | I30: 30023055 | N30: P002801 BBS Holder Front Reinf Bend | O30: =O27 -> 1 | P30: 18 | Q30: SCEBEA02 | R30: =$AB$1/P30 -> 200 | Y30: =$Y$1/R30 -> 5 | AB30: =$Y$1/R30 -> 5 | AE30: =$Y$1/R30 -> 5 | AH30: =$Y$1/R30 -> 5 | AK30: =$Y$1/R30 -> 5 | AN30: =$Y$1/R30 -> 5
B31: L | J31: 30022130 | N31: P002801 BBS Holder Front Reinf Laser | O31: =O30 -> 1 | P31: 13 | Q31: SCECUA04 | R31: =$AB$1/P31 -> 276.92308 | Y31: =$Y$1/R31 -> 3.6111111 | AB31: =$Y$1/R31 -> 3.6111111 | AE31: =$Y$1/R31 -> 3.6111111 | AH31: =$Y$1/R31 -> 3.6111111 | AK31: =$Y$1/R31 -> 3.6111111 | AN31: =$Y$1/R31 -> 3.6111111
B32: L | K32: 10030768 | N32: P002801 BBS Holder Front Reinf GP | O32: =O31 -> 1
B33: L | H33: 30023063 | N33: P002954 BBS Holder Rear Left Press | O33: =O17 -> 1 | P33: 12 | Q33: SCESBA01 | R33: =$AB$1/P33 -> 300 | Y33: =$Y$1/R33 -> 3.3333333 | AB33: =$Y$1/R33 -> 3.3333333 | AE33: =$Y$1/R33 -> 3.3333333 | AH33: =$Y$1/R33 -> 3.3333333 | AK33: =$Y$1/R33 -> 3.3333333 | AN33: =$Y$1/R33 -> 3.3333333
B34: L | I34: 10034388 | N34: P002954 BBS Holder Rear Left GP | O34: =O33 -> 1
B35: L | H35: 30023064 | N35: P002955 BBS Holder Rear Right Press | O35: =O19 -> 1 | P35: 12 | Q35: SCESBA01 | R35: =$AB$1/P35 -> 300 | Y35: =$Y$1/R35 -> 3.3333333 | AB35: =$Y$1/R35 -> 3.3333333 | AE35: =$Y$1/R35 -> 3.3333333 | AH35: =$Y$1/R35 -> 3.3333333 | AK35: =$Y$1/R35 -> 3.3333333 | AN35: =$Y$1/R35 -> 3.3333333
B36: L | I36: 10034389 | N36: P002955 BBS Holder Rear Right GP | O36: =O35 -> 1
B37: L | H37: 30023050 | N37: P002622 Locking Slide Bend | O37: =O17 -> 1 | P37: 36 | Q37: SCEBEA02 | R37: =$AB$1/P37 -> 100 | Y37: =$Y$1/R37 -> 10 | AB37: =$Y$1/R37 -> 10 | AE37: =$Y$1/R37 -> 10 | AH37: =$Y$1/R37 -> 10 | AK37: =$Y$1/R37 -> 10 | AN37: =$Y$1/R37 -> 10
B38: L | I38: 30023145 | N38: P002622 Locking Slide Laser | O38: =O37 -> 1 | P38: 8 | Q38: SCECUA04 | R38: 450 | Y38: 125 | AB38: 125 | AE38: 125 | AH38: 125 | AK38: 125 | AN38: 125
B39: L | J39: 10034294 | N39: P002622 Locking Slide GP | O39: =O37 -> 1
B40: L | H40: 30023053 | N40: P002626 Cover Support Spot | O40: =O17*2 -> 2 | P40: 32 | Q40: SCESGA01 | R40: =$AB$1/P40 -> 112.5 | Y40: =$Y$1/R40 -> 8.8888889 | AB40: =$Y$1/R40 -> 8.8888889 | AE40: =$Y$1/R40 -> 8.8888889 | AH40: =$Y$1/R40 -> 8.8888889 | AK40: =$Y$1/R40 -> 8.8888889 | AN40: =$Y$1/R40 -> 8.8888889
B41: L | I41: 30023051 | N41: P002626 Cover Support Bend | O41: =O40 -> 2 | P41: 18 | Q41: SCEBEA02 | R41: =$AB$1/P41 -> 200 | Y41: =$Y$1/R41 -> 5 | AB41: =$Y$1/R41 -> 5 | AE41: =$Y$1/R41 -> 5 | AH41: =$Y$1/R41 -> 5 | AK41: =$Y$1/R41 -> 5 | AN41: =$Y$1/R41 -> 5
...

Sheet CPI27 (5)
A1: NO | B1: Status | M1: Remark | N1: PART NAME (Geelong ) | O1: Q'TY | Q1: Work Center | R1: CT | S1: Alt. BOM | T1: Group Center | U1: Seq. | V1: Operation | W1: Group | Y1: 1000 | AB1: 3600
B3: L | C3: 40012178 | N3: TC-2707TSR | O3: 1 | P3: 22.5 | Q3: SCEASA01 | R3: =$AB$1/P3 -> 160 | Y3: =$Y$1/R3 -> 6.25 | AB3: =$Y$1/R3 -> 6.25 | AE3: =$Y$1/R3 -> 6.25 | AH3: =$Y$1/R3 -> 6.25 | AK3: =$Y$1/R3 -> 6.25 | AN3: =$Y$1/R3 -> 6.25
B4: L | D4: 30022112 | N4: U000433 Box Paint | O4: =O3 -> 1 | P4: 22.5 | Q4: SCECOA01 | R4: =$AB$1/P4 -> 160 | Y4: =$Y$1/R4 -> 6.25 | AB4: =$Y$1/R4 -> 6.25 | AE4: =$Y$1/R4 -> 6.25 | AH4: =$Y$1/R4 -> 6.25 | AK4: =$Y$1/R4 -> 6.25 | AN4: =$Y$1/R4 -> 6.25
B5: L | E5: 30022113 | N5: U000433 Box Weld | O5: =O4 -> 1 | P5: =180+60 -> 240 | Q5: SCEGWA01 | R5: =$AB$1/P5 -> 15 | Y5: =$Y$1/R5 -> 66.666667 | AB5: =$Y$1/R5 -> 66.666667 | AE5: =$Y$1/R5 -> 66.666667 | AH5: =$Y$1/R5 -> 66.666667 | AK5: =$Y$1/R5 -> 66.666667 | AN5: =$Y$1/R5 -> 66.666667
B6: L | F6: 30022114 | N6: U000433 Box Spot | O6: =O5 -> 1 | P6: =350 -> 350 | Q6: SCESGA01 | R6: =$AB$1/P6 -> 10.285714 | Y6: =$Y$1/R6 -> 97.222222 | AB6: =$Y$1/R6 -> 97.222222 | AE6: =$Y$1/R6 -> 97.222222 | AH6: =$Y$1/R6 -> 97.222222 | AK6: =$Y$1/R6 -> 97.222222 | AN6: =$Y$1/R6 -> 97.222222
B7: L | G7: 30022115 | N7: P002732 Top Cover Spot | O7: =O6 -> 1 | P7: 10 | Q7: SCESGA01 | R7: =$AB$1/P7 -> 360 | Y7: =$Y$1/R7 -> 2.7777778 | AB7: =$Y$1/R7 -> 2.7777778 | AE7: =$Y$1/R7 -> 2.7777778 | AH7: =$Y$1/R7 -> 2.7777778 | AK7: =$Y$1/R7 -> 2.7777778 | AN7: =$Y$1/R7 -> 2.7777778
B8: L | H8: 30022116 | N8: P002732 Top Cover Bend | O8: =O7 -> 1 | P8: 18 | Q8: SCEBEA02 | R8: =$AB$1/P8 -> 200 | Y8: =$Y$1/R8 -> 5 | AB8: =$Y$1/R8 -> 5 | AE8: =$Y$1/R8 -> 5 | AH8: =$Y$1/R8 -> 5 | AK8: =$Y$1/R8 -> 5 | AN8: =$Y$1/R8 -> 5
B9: L | I9: 30022117 | N9: P002732 Top Cover IPC | O9: =O8 -> 1
B10: L | J10: 10030761 | N10: P002732 Top Cover GP | O10: =O9 -> 1
B11: L | H11: 10030762 | N11: P002571 Hook Holder GP | O11: =O7 -> 1
B12: L | G12: 30022119 | N12: P002733 Bottom Back Bend | O12: =O6 -> 1 | P12: 9 | Q12: SCEBEA02 | R12: =$AB$1/P12 -> 400 | Y12: =$Y$1/R12 -> 2.5 | AB12: =$Y$1/R12 -> 2.5 | AE12: =$Y$1/R12 -> 2.5 | AH12: =$Y$1/R12 -> 2.5 | AK12: =$Y$1/R12 -> 2.5 | AN12: =$Y$1/R12 -> 2.5
B13: L | H13: 30022120 | N13: P002733 Bottom Back IPC | O13: =O12 -> 1
B14: L | I14: 10030763 | N14: P002733 Bottom Back GP | O14: =O13 -> 1
B15: L | G15: 30022121 | N15: P002734 Bottom Cover Reinf Bend | O15: =O6*2 -> 2 | P15: 27 | Q15: SCEBEA02 | R15: =$AB$1/P15 -> 133.33333 | Y15: =$Y$1/R15 -> 7.5 | AB15: =$Y$1/R15 -> 7.5 | AE15: =$Y$1/R15 -> 7.5 | AH15: =$Y$1/R15 -> 7.5 | AK15: =$Y$1/R15 -> 7.5 | AN15: =$Y$1/R15 -> 7.5
B16: L | H16: 10030764 | N16: P002734 Bottom Cover Reinf GP | O16: =O15 -> 2
B17: L | G17: 30023058 | N17: P002951 Box Spot | O17: =O6 -> 1 | P17: =40+40+75+75+45+80 -> 355 | Q17: SCESGA01 | R17: =$AB$1/P17 -> 10.140845 | Y17: =$Y$1/R17 -> 98.611111 | AB17: =$Y$1/R17 -> 98.611111 | AE17: =$Y$1/R17 -> 98.611111 | AH17: =$Y$1/R17 -> 98.611111 | AK17: =$Y$1/R17 -> 98.611111 | AN17: =$Y$1/R17 -> 98.611111
B18: L | H18: 30023056 | N18: P002951 Box Bend | O18: =O17 -> 1 | P18: 54 | Q18: SCESBA01 | R18: =$AB$1/P18 -> 66.666667 | Y18: =$Y$1/R18 -> 15 | AB18: =$Y$1/R18 -> 15 | AE18: =$Y$1/R18 -> 15 | AH18: =$Y$1/R18 -> 15 | AK18: =$Y$1/R18 -> 15 | AN18: =$Y$1/R18 -> 15
B19: L | I19: 30023057 | N19: P002951 Box Press | O19: =O17 -> 1 | P19: 24 | Q19: SCESBA01 | R19: =$AB$1/P19 -> 150 | Y19: =$Y$1/R19 -> 6.6666667 | AB19: =$Y$1/R19 -> 6.6666667 | AE19: =$Y$1/R19 -> 6.6666667 | AH19: =$Y$1/R19 -> 6.6666667 | AK19: =$Y$1/R19 -> 6.6666667 | AN19: =$Y$1/R19 -> 6.6666667
B20: L | J20: 10034385 | N20: P002951 Box GP | O20: =O19 -> 1
B21: L | H21: 30023060 | N21: P002952 BBS Holder Front Left Spot | O21: =O17 -> 1 | P21: 50 | Q21: SCESGA01 | R21: =$AB$1/P21 -> 72 | Y21: =$Y$1/R21 -> 13.888889 | AB21: =$Y$1/R21 -> 13.888889 | AE21: =$Y$1/R21 -> 13.888889 | AH21: =$Y$1/R21 -> 13.888889 | AK21: =$Y$1/R21 -> 13.888889 | AN21: =$Y$1/R21 -> 13.888889
B22: L | I22: 30023059 | N22: P002952 BBS Holder Front Left Press | O22: =O19 -> 1 | P22: 12 | Q22: SCESBA01 | R22: =$AB$1/P22 -> 300 | Y22: =$Y$1/R22 -> 3.3333333 | AB22: =$Y$1/R22 -> 3.3333333 | AE22: =$Y$1/R22 -> 3.3333333 | AH22: =$Y$1/R22 -> 3.3333333 | AK22: =$Y$1/R22 -> 3.3333333 | AN22: =$Y$1/R22 -> 3.3333333
B23: L | J23: 10034386 | N23: P002952 BBS Holder Front Left GP | O23: =O20 -> 1
B24: L | I24: 30023055 | N24: P002801 BBS Holder Front Reinf Bend | O24: =O21 -> 1 | P24: 18 | Q24: SCEBEA02 | R24: =$AB$1/P24 -> 200 | Y24: =$Y$1/R24 -> 5 | AB24: =$Y$1/R24 -> 5 | AE24: =$Y$1/R24 -> 5 | AH24: =$Y$1/R24 -> 5 | AK24: =$Y$1/R24 -> 5 | AN24: =$Y$1/R24 -> 5
B25: L | J25: 30022130 | N25: P002801 BBS Holder Front Reinf Laser | O25: =O24 -> 1 | P25: 13 | Q25: SCECUA04 | R25: =$AB$1/P25 -> 276.92308 | Y25: =$Y$1/R25 -> 3.6111111 | AB25: =$Y$1/R25 -> 3.6111111 | AE25: =$Y$1/R25 -> 3.6111111 | AH25: =$Y$1/R25 -> 3.6111111 | AK25: =$Y$1/R25 -> 3.6111111 | AN25: =$Y$1/R25 -> 3.6111111
B26: L | K26: 10030768 | N26: P002801 BBS Holder Front Reinf GP | O26: =O25 -> 1
B27: L | H27: 30023062 | N27: P002953 BBS Holder Front Right Spot | O27: =O19 -> 1 | P27: 50 | Q27: SCESGA01 | R27: =$AB$1/P27 -> 72 | Y27: =$Y$1/R27 -> 13.888889 | AB27: =$Y$1/R27 -> 13.888889 | AE27: =$Y$1/R27 -> 13.888889 | AH27: =$Y$1/R27 -> 13.888889 | AK27: =$Y$1/R27 -> 13.888889 | AN27: =$Y$1/R27 -> 13.888889
B28: L | I28: 30023061 | N28: P002953 BBS Holder Front Right Press | O28: =O27 -> 1 | P28: 12 | Q28: SCESBA01 | R28: =$AB$1/P28 -> 300 | Y28: =$Y$1/R28 -> 3.3333333 | AB28: =$Y$1/R28 -> 3.3333333 | AE28: =$Y$1/R28 -> 3.3333333 | AH28: =$Y$1/R28 -> 3.3333333 | AK28: =$Y$1/R28 -> 3.3333333 | AN28: =$Y$1/R28 -> 3.3333333
B29: L | J29: 10034387 | N29: P002953 BBS Holder Front Right GP | O29: =O28 -> 1
B30: L | I30: 30023055 | N30: P002801 BBS Holder Front Reinf Bend | O30: =O27 -> 1 | P30: 18 | Q30: SCEBEA02 | R30: =$AB$1/P30 -> 200 | Y30: =$Y$1/R30 -> 5 | AB30: =$Y$1/R30 -> 5 | AE30: =$Y$1/R30 -> 5 | AH30: =$Y$1/R30 -> 5 | AK30: =$Y$1/R30 -> 5 | AN30: =$Y$1/R30 -> 5
B31: L | J31: 30022130 | N31: P002801 BBS Holder Front Reinf Laser | O31: =O30 -> 1 | P31: 13 | Q31: SCECUA04 | R31: =$AB$1/P31 -> 276.92308 | Y31: =$Y$1/R31 -> 3.6111111 | AB31: =$Y$1/R31 -> 3.6111111 | AE31: =$Y$1/R31 -> 3.6111111 | AH31: =$Y$1/R31 -> 3.6111111 | AK31: =$Y$1/R31 -> 3.6111111 | AN31: =$Y$1/R31 -> 3.6111111
B32: L | K32: 10030768 | N32: P002801 BBS Holder Front Reinf GP | O32: =O31 -> 1
B33: L | H33: 30023063 | N33: P002954 BBS Holder Rear Left Press | O33: =O17 -> 1 | P33: 12 | Q33: SCESBA01 | R33: =$AB$1/P33 -> 300 | Y33: =$Y$1/R33 -> 3.3333333 | AB33: =$Y$1/R33 -> 3.3333333 | AE33: =$Y$1/R33 -> 3.3333333 | AH33: =$Y$1/R33 -> 3.3333333 | AK33: =$Y$1/R33 -> 3.3333333 | AN33: =$Y$1/R33 -> 3.3333333
B34: L | I34: 10034388 | N34: P002954 BBS Holder Rear Left GP | O34: =O33 -> 1
B35: L | H35: 30023064 | N35: P002955 BBS Holder Rear Right Press | O35: =O19 -> 1 | P35: 12 | Q35: SCESBA01 | R35: =$AB$1/P35 -> 300 | Y35: =$Y$1/R35 -> 3.3333333 | AB35: =$Y$1/R35 -> 3.3333333 | AE35: =$Y$1/R35 -> 3.3333333 | AH35: =$Y$1/R35 -> 3.3333333 | AK35: =$Y$1/R35 -> 3.3333333 | AN35: =$Y$1/R35 -> 3.3333333
B36: L | I36: 10034389 | N36: P002955 BBS Holder Rear Right GP | O36: =O35 -> 1
B37: L | H37: 30023050 | N37: P002622 Locking Slide Bend | O37: =O17 -> 1 | P37: 36 | Q37: SCEBEA02 | R37: =$AB$1/P37 -> 100 | Y37: =$Y$1/R37 -> 10 | AB37: =$Y$1/R37 -> 10 | AE37: =$Y$1/R37 -> 10 | AH37: =$Y$1/R37 -> 10 | AK37: =$Y$1/R37 -> 10 | AN37: =$Y$1/R37 -> 10
B38: L | I38: 30023145 | N38: P002622 Locking Slide Laser | O38: =O37 -> 1 | P38: 8 | Q38: SCECUA04 | R38: 450 | Y38: 125 | AB38: 125 | AE38: 125 | AH38: 125 | AK38: 125 | AN38: 125
B39: L | J39: 10034294 | N39: P002622 Locking Slide GP | O39: =O37 -> 1
B40: L | H40: 30023053 | N40: P002626 Cover Support Spot | O40: =O17*2 -> 2 | P40: 32 | Q40: SCESGA01 | R40: =$AB$1/P40 -> 112.5 | Y40: =$Y$1/R40 -> 8.8888889 | AB40: =$Y$1/R40 -> 8.8888889 | AE40: =$Y$1/R40 -> 8.8888889 | AH40: =$Y$1/R40 -> 8.8888889 | AK40: =$Y$1/R40 -> 8.8888889 | AN40: =$Y$1/R40 -> 8.8888889
B41: L | I41: 30023051 | N41: P002626 Cover Support Bend | O41: =O40 -> 2 | P41: 18 | Q41: SCEBEA02 | R41: =$AB$1/P41 -> 200 | Y41: =$Y$1/R41 -> 5 | AB41: =$Y$1/R41 -> 5 | AE41: =$Y$1/R41 -> 5 | AH41: =$Y$1/R41 -> 5 | AK41: =$Y$1/R41 -> 5 | AN41: =$Y$1/R41 -> 5
...

Sheet TC27 (6)
A1: NO | B1: Status | M1: Remark | N1: PART NAME (Geelong ) | O1: Q'TY | Q1: Work Center | R1: CT | S1: Alt. BOM | T1: Group Center | U1: Seq. | V1: Operation | W1: Group | Y1: 1000 | AB1: 3600
B3: L | C3: 40012178 | N3: TC-2707TSR | O3: 1 | P3: 22.5 | Q3: SCEASA01 | R3: =$AB$1/P3 -> 160 | Y3: =$Y$1/R3 -> 6.25 | AB3: =$Y$1/R3 -> 6.25 | AE3: =$Y$1/R3 -> 6.25 | AH3: =$Y$1/R3 -> 6.25 | AK3: =$Y$1/R3 -> 6.25 | AN3: =$Y$1/R3 -> 6.25
B4: L | D4: 30022112 | N4: U000433 Box Paint | O4: =O3 -> 1 | P4: 22.5 | Q4: SCECOA01 | R4: =$AB$1/P4 -> 160 | Y4: =$Y$1/R4 -> 6.25 | AB4: =$Y$1/R4 -> 6.25 | AE4: =$Y$1/R4 -> 6.25 | AH4: =$Y$1/R4 -> 6.25 | AK4: =$Y$1/R4 -> 6.25 | AN4: =$Y$1/R4 -> 6.25
B5: L | E5: 30022113 | N5: U000433 Box Weld | O5: =O4 -> 1 | P5: =180+60 -> 240 | Q5: SCEGWA01 | R5: =$AB$1/P5 -> 15 | Y5: =$Y$1/R5 -> 66.666667 | AB5: =$Y$1/R5 -> 66.666667 | AE5: =$Y$1/R5 -> 66.666667 | AH5: =$Y$1/R5 -> 66.666667 | AK5: =$Y$1/R5 -> 66.666667 | AN5: =$Y$1/R5 -> 66.666667
B6: L | F6: 30022114 | N6: U000433 Box Spot | O6: =O5 -> 1 | P6: =350 -> 350 | Q6: SCESGA01 | R6: =$AB$1/P6 -> 10.285714 | Y6: =$Y$1/R6 -> 97.222222 | AB6: =$Y$1/R6 -> 97.222222 | AE6: =$Y$1/R6 -> 97.222222 | AH6: =$Y$1/R6 -> 97.222222 | AK6: =$Y$1/R6 -> 97.222222 | AN6: =$Y$1/R6 -> 97.222222
B7: L | G7: 30022115 | N7: P002732 Top Cover Spot | O7: =O6 -> 1 | P7: 10 | Q7: SCESGA01 | R7: =$AB$1/P7 -> 360 | Y7: =$Y$1/R7 -> 2.7777778 | AB7: =$Y$1/R7 -> 2.7777778 | AE7: =$Y$1/R7 -> 2.7777778 | AH7: =$Y$1/R7 -> 2.7777778 | AK7: =$Y$1/R7 -> 2.7777778 | AN7: =$Y$1/R7 -> 2.7777778
B8: L | H8: 30022116 | N8: P002732 Top Cover Bend | O8: =O7 -> 1 | P8: 18 | Q8: SCEBEA02 | R8: =$AB$1/P8 -> 200 | Y8: =$Y$1/R8 -> 5 | AB8: =$Y$1/R8 -> 5 | AE8: =$Y$1/R8 -> 5 | AH8: =$Y$1/R8 -> 5 | AK8: =$Y$1/R8 -> 5 | AN8: =$Y$1/R8 -> 5
B9: L | I9: 30022117 | N9: P002732 Top Cover IPC | O9: =O8 -> 1
B10: L | J10: 10030761 | N10: P002732 Top Cover GP | O10: =O9 -> 1
B11: L | H11: 10030762 | N11: P002571 Hook Holder GP | O11: =O7 -> 1
B12: L | G12: 30022119 | N12: P002733 Bottom Back Bend | O12: =O6 -> 1 | P12: 9 | Q12: SCEBEA02 | R12: =$AB$1/P12 -> 400 | Y12: =$Y$1/R12 -> 2.5 | AB12: =$Y$1/R12 -> 2.5 | AE12: =$Y$1/R12 -> 2.5 | AH12: =$Y$1/R12 -> 2.5 | AK12: =$Y$1/R12 -> 2.5 | AN12: =$Y$1/R12 -> 2.5
B13: L | H13: 30022120 | N13: P002733 Bottom Back IPC | O13: =O12 -> 1
B14: L | I14: 10030763 | N14: P002733 Bottom Back GP | O14: =O13 -> 1
B15: L | G15: 30022121 | N15: P002734 Bottom Cover Reinf Bend | O15: =O6*2 -> 2 | P15: 27 | Q15: SCEBEA02 | R15: =$AB$1/P15 -> 133.33333 | Y15: =$Y$1/R15 -> 7.5 | AB15: =$Y$1/R15 -> 7.5 | AE15: =$Y$1/R15 -> 7.5 | AH15: =$Y$1/R15 -> 7.5 | AK15: =$Y$1/R15 -> 7.5 | AN15: =$Y$1/R15 -> 7.5
B16: L | H16: 10030764 | N16: P002734 Bottom Cover Reinf GP | O16: =O15 -> 2
B17: L | G17: 30023058 | N17: P002951 Box Spot | O17: =O6 -> 1 | P17: =40+40+75+75+45+80 -> 355 | Q17: SCESGA01 | R17: =$AB$1/P17 -> 10.140845 | Y17: =$Y$1/R17 -> 98.611111 | AB17: =$Y$1/R17 -> 98.611111 | AE17: =$Y$1/R17 -> 98.611111 | AH17: =$Y$1/R17 -> 98.611111 | AK17: =$Y$1/R17 -> 98.611111 | AN17: =$Y$1/R17 -> 98.611111
B18: L | H18: 30023056 | N18: P002951 Box Bend | O18: =O17 -> 1 | P18: 54 | Q18: SCESBA01 | R18: =$AB$1/P18 -> 66.666667 | Y18: =$Y$1/R18 -> 15 | AB18: =$Y$1/R18 -> 15 | AE18: =$Y$1/R18 -> 15 | AH18: =$Y$1/R18 -> 15 | AK18: =$Y$1/R18 -> 15 | AN18: =$Y$1/R18 -> 15
B19: L | I19: 30023057 | N19: P002951 Box Press | O19: =O17 -> 1 | P19: 24 | Q19: SCESBA01 | R19: =$AB$1/P19 -> 150 | Y19: =$Y$1/R19 -> 6.6666667 | AB19: =$Y$1/R19 -> 6.6666667 | AE19: =$Y$1/R19 -> 6.6666667 | AH19: =$Y$1/R19 -> 6.6666667 | AK19: =$Y$1/R19 -> 6.6666667 | AN19: =$Y$1/R19 -> 6.6666667
B20: L | J20: 10034385 | N20: P002951 Box GP | O20: =O19 -> 1
B21: L | H21: 30023060 | N21: P002952 BBS Holder Front Left Spot | O21: =O17 -> 1 | P21: 50 | Q21: SCESGA01 | R21: =$AB$1/P21 -> 72 | Y21: =$Y$1/R21 -> 13.888889 | AB21: =$Y$1/R21 -> 13.888889 | AE21: =$Y$1/R21 -> 13.888889 | AH21: =$Y$1/R21 -> 13.888889 | AK21: =$Y$1/R21 -> 13.888889 | AN21: =$Y$1/R21 -> 13.888889
B22: L | I22: 30023059 | N22: P002952 BBS Holder Front Left Press | O22: =O19 -> 1 | P22: 12 | Q22: SCESBA01 | R22: =$AB$1/P22 -> 300 | Y22: =$Y$1/R22 -> 3.3333333 | AB22: =$Y$1/R22 -> 3.3333333 | AE22: =$Y$1/R22 -> 3.3333333 | AH22: =$Y$1/R22 -> 3.3333333 | AK22: =$Y$1/R22 -> 3.3333333 | AN22: =$Y$1/R22 -> 3.3333333
B23: L | J23: 10034386 | N23: P002952 BBS Holder Front Left GP | O23: =O20 -> 1
B24: L | I24: 30023055 | N24: P002801 BBS Holder Front Reinf Bend | O24: =O21 -> 1 | P24: 18 | Q24: SCEBEA02 | R24: =$AB$1/P24 -> 200 | Y24: =$Y$1/R24 -> 5 | AB24: =$Y$1/R24 -> 5 | AE24: =$Y$1/R24 -> 5 | AH24: =$Y$1/R24 -> 5 | AK24: =$Y$1/R24 -> 5 | AN24: =$Y$1/R24 -> 5
B25: L | J25: 30022130 | N25: P002801 BBS Holder Front Reinf Laser | O25: =O24 -> 1 | P25: 13 | Q25: SCECUA04 | R25: =$AB$1/P25 -> 276.92308 | Y25: =$Y$1/R25 -> 3.6111111 | AB25: =$Y$1/R25 -> 3.6111111 | AE25: =$Y$1/R25 -> 3.6111111 | AH25: =$Y$1/R25 -> 3.6111111 | AK25: =$Y$1/R25 -> 3.6111111 | AN25: =$Y$1/R25 -> 3.6111111
B26: L | K26: 10030768 | N26: P002801 BBS Holder Front Reinf GP | O26: =O25 -> 1
B27: L | H27: 30023062 | N27: P002953 BBS Holder Front Right Spot | O27: =O19 -> 1 | P27: 50 | Q27: SCESGA01 | R27: =$AB$1/P27 -> 72 | Y27: =$Y$1/R27 -> 13.888889 | AB27: =$Y$1/R27 -> 13.888889 | AE27: =$Y$1/R27 -> 13.888889 | AH27: =$Y$1/R27 -> 13.888889 | AK27: =$Y$1/R27 -> 13.888889 | AN27: =$Y$1/R27 -> 13.888889
B28: L | I28: 30023061 | N28: P002953 BBS Holder Front Right Press | O28: =O27 -> 1 | P28: 12 | Q28: SCESBA01 | R28: =$AB$1/P28 -> 300 | Y28: =$Y$1/R28 -> 3.3333333 | AB28: =$Y$1/R28 -> 3.3333333 | AE28: =$Y$1/R28 -> 3.3333333 | AH28: =$Y$1/R28 -> 3.3333333 | AK28: =$Y$1/R28 -> 3.3333333 | AN28: =$Y$1/R28 -> 3.3333333
B29: L | J29: 10034387 | N29: P002953 BBS Holder Front Right GP | O29: =O28 -> 1
B30: L | I30: 30023055 | N30: P002801 BBS Holder Front Reinf Bend | O30: =O27 -> 1 | P30: 18 | Q30: SCEBEA02 | R30: =$AB$1/P30 -> 200 | Y30: =$Y$1/R30 -> 5 | AB30: =$Y$1/R30 -> 5 | AE30: =$Y$1/R30 -> 5 | AH30: =$Y$1/R30 -> 5 | AK30: =$Y$1/R30 -> 5 | AN30: =$Y$1/R30 -> 5
B31: L | J31: 30022130 | N31: P002801 BBS Holder Front Reinf Laser | O31: =O30 -> 1 | P31: 13 | Q31: SCECUA04 | R31: =$AB$1/P31 -> 276.92308 | Y31: =$Y$1/R31 -> 3.6111111 | AB31: =$Y$1/R31 -> 3.6111111 | AE31: =$Y$1/R31 -> 3.6111111 | AH31: =$Y$1/R31 -> 3.6111111 | AK31: =$Y$1/R31 -> 3.6111111 | AN31: =$Y$1/R31 -> 3.6111111
B32: L | K32: 10030768 | N32: P002801 BBS Holder Front Reinf GP | O32: =O31 -> 1
B33: L | H33: 30023063 | N33: P002954 BBS Holder Rear Left Press | O33: =O17 -> 1 | P33: 12 | Q33: SCESBA01 | R33: =$AB$1/P33 -> 300 | Y33: =$Y$1/R33 -> 3.3333333 | AB33: =$Y$1/R33 -> 3.3333333 | AE33: =$Y$1/R33 -> 3.3333333 | AH33: =$Y$1/R33 -> 3.3333333 | AK33: =$Y$1/R33 -> 3.3333333 | AN33: =$Y$1/R33 -> 3.3333333
B34: L | I34: 10034388 | N34: P002954 BBS Holder Rear Left GP | O34: =O33 -> 1
B35: L | H35: 30023064 | N35: P002955 BBS Holder Rear Right Press | O35: =O19 -> 1 | P35: 12 | Q35: SCESBA01 | R35: =$AB$1/P35 -> 300 | Y35: =$Y$1/R35 -> 3.3333333 | AB35: =$Y$1/R35 -> 3.3333333 | AE35: =$Y$1/R35 -> 3.3333333 | AH35: =$Y$1/R35 -> 3.3333333 | AK35: =$Y$1/R35 -> 3.3333333 | AN35: =$Y$1/R35 -> 3.3333333
B36: L | I36: 10034389 | N36: P002955 BBS Holder Rear Right GP | O36: =O35 -> 1
B37: L | H37: 30023050 | N37: P002622 Locking Slide Bend | O37: =O17 -> 1 | P37: 36 | Q37: SCEBEA02 | R37: =$AB$1/P37 -> 100 | Y37: =$Y$1/R37 -> 10 | AB37: =$Y$1/R37 -> 10 | AE37: =$Y$1/R37 -> 10 | AH37: =$Y$1/R37 -> 10 | AK37: =$Y$1/R37 -> 10 | AN37: =$Y$1/R37 -> 10
B38: L | I38: 30023145 | N38: P002622 Locking Slide Laser | O38: =O37 -> 1 | P38: 8 | Q38: SCECUA04 | R38: 450 | Y38: 125 | AB38: 125 | AE38: 125 | AH38: 125 | AK38: 125 | AN38: 125
B39: L | J39: 10034294 | N39: P002622 Locking Slide GP | O39: =O37 -> 1
B40: L | H40: 30023053 | N40: P002626 Cover Support Spot | O40: =O17*2 -> 2 | P40: 32 | Q40: SCESGA01 | R40: =$AB$1/P40 -> 112.5 | Y40: =$Y$1/R40 -> 8.8888889 | AB40: =$Y$1/R40 -> 8.8888889 | AE40: =$Y$1/R40 -> 8.8888889 | AH40: =$Y$1/R40 -> 8.8888889 | AK40: =$Y$1/R40 -> 8.8888889 | AN40: =$Y$1/R40 -> 8.8888889
B41: L | I41: 30023051 | N41: P002626 Cover Support Bend | O41: =O40 -> 2 | P41: 18 | Q41: SCEBEA02 | R41: =$AB$1/P41 -> 200 | Y41: =$Y$1/R41 -> 5 | AB41: =$Y$1/R41 -> 5 | AE41: =$Y$1/R41 -> 5 | AH41: =$Y$1/R41 -> 5 | AK41: =$Y$1/R41 -> 5 | AN41: =$Y$1/R41 -> 5
...

Sheet TC27 (16-7-2025)
A1: NO | B1: Status | M1: Remark | N1: PART NAME (Geelong ) | O1: Q'TY | Q1: Work Center | R1: CT | S1: Alt. BOM | T1: Group Center | U1: Seq. | V1: Operation | W1: Group | Y1: 1000 | AB1: 3600
B3: L | C3: 40012178 | N3: TC-2707TSR | O3: 1 | P3: 22.5 | Q3: SCEASA01 | R3: =$AB$1/P3 -> 160 | Y3: =$Y$1/R3 -> 6.25 | AB3: =$Y$1/R3 -> 6.25 | AE3: =$Y$1/R3 -> 6.25 | AH3: =$Y$1/R3 -> 6.25 | AK3: =$Y$1/R3 -> 6.25 | AN3: =$Y$1/R3 -> 6.25
B4: L | D4: 30022112 | N4: U000433 Box Paint | O4: =O3 -> 1 | P4: 22.5 | Q4: SCECOA01 | R4: =$AB$1/P4 -> 160 | Y4: =$Y$1/R4 -> 6.25 | AB4: =$Y$1/R4 -> 6.25 | AE4: =$Y$1/R4 -> 6.25 | AH4: =$Y$1/R4 -> 6.25 | AK4: =$Y$1/R4 -> 6.25 | AN4: =$Y$1/R4 -> 6.25
B5: L | E5: 30022113 | N5: U000433 Box Weld | O5: =O4 -> 1 | P5: =180+60 -> 240 | Q5: SCEGWA01 | R5: =$AB$1/P5 -> 15 | Y5: =$Y$1/R5 -> 66.666667 | AB5: =$Y$1/R5 -> 66.666667 | AE5: =$Y$1/R5 -> 66.666667 | AH5: =$Y$1/R5 -> 66.666667 | AK5: =$Y$1/R5 -> 66.666667 | AN5: =$Y$1/R5 -> 66.666667
B6: L | F6: 30022114 | N6: U000433 Box Spot | O6: =O5 -> 1 | P6: =350 -> 350 | Q6: SCESGA01 | R6: =$AB$1/P6 -> 10.285714 | Y6: =$Y$1/R6 -> 97.222222 | AB6: =$Y$1/R6 -> 97.222222 | AE6: =$Y$1/R6 -> 97.222222 | AH6: =$Y$1/R6 -> 97.222222 | AK6: =$Y$1/R6 -> 97.222222 | AN6: =$Y$1/R6 -> 97.222222
B7: L | G7: 30022115 | N7: P002732 Top Cover Spot | O7: =O6 -> 1 | P7: 10 | Q7: SCESGA01 | R7: =$AB$1/P7 -> 360 | Y7: =$Y$1/R7 -> 2.7777778 | AB7: =$Y$1/R7 -> 2.7777778 | AE7: =$Y$1/R7 -> 2.7777778 | AH7: =$Y$1/R7 -> 2.7777778 | AK7: =$Y$1/R7 -> 2.7777778 | AN7: =$Y$1/R7 -> 2.7777778
B8: L | H8: 30022116 | N8: P002732 Top Cover Bend | O8: =O7 -> 1 | P8: 18 | Q8: SCEBEA02 | R8: =$AB$1/P8 -> 200 | Y8: =$Y$1/R8 -> 5 | AB8: =$Y$1/R8 -> 5 | AE8: =$Y$1/R8 -> 5 | AH8: =$Y$1/R8 -> 5 | AK8: =$Y$1/R8 -> 5 | AN8: =$Y$1/R8 -> 5
B9: L | I9: 30022117 | N9: P002732 Top Cover IPC | O9: =O8 -> 1
B10: L | J10: 10030761 | N10: P002732 Top Cover GP | O10: =O9 -> 1
B11: L | H11: 10030762 | N11: P002571 Hook Holder GP | O11: =O7 -> 1
B12: L | G12: 30022119 | N12: P002733 Bottom Back Bend | O12: =O6 -> 1 | P12: 9 | Q12: SCEBEA02 | R12: =$AB$1/P12 -> 400 | Y12: =$Y$1/R12 -> 2.5 | AB12: =$Y$1/R12 -> 2.5 | AE12: =$Y$1/R12 -> 2.5 | AH12: =$Y$1/R12 -> 2.5 | AK12: =$Y$1/R12 -> 2.5 | AN12: =$Y$1/R12 -> 2.5
B13: L | H13: 30022120 | N13: P002733 Bottom Back IPC | O13: =O12 -> 1
B14: L | I14: 10030763 | N14: P002733 Bottom Back GP | O14: =O13 -> 1
B15: L | G15: 30022121 | N15: P002734 Bottom Cover Reinf Bend | O15: =O6*2 -> 2 | P15: 27 | Q15: SCEBEA02 | R15: =$AB$1/P15 -> 133.33333 | Y15: =$Y$1/R15 -> 7.5 | AB15: =$Y$1/R15 -> 7.5 | AE15: =$Y$1/R15 -> 7.5 | AH15: =$Y$1/R15 -> 7.5 | AK15: =$Y$1/R15 -> 7.5 | AN15: =$Y$1/R15 -> 7.5
B16: L | H16: 10030764 | N16: P002734 Bottom Cover Reinf GP | O16: =O15 -> 2
B17: L | G17: 30023058 | N17: P002951 Box Spot | O17: =O6 -> 1 | P17: =40+40+75+75+45+80 -> 355 | Q17: SCESGA01 | R17: =$AB$1/P17 -> 10.140845 | Y17: =$Y$1/R17 -> 98.611111 | AB17: =$Y$1/R17 -> 98.611111 | AE17: =$Y$1/R17 -> 98.611111 | AH17: =$Y$1/R17 -> 98.611111 | AK17: =$Y$1/R17 -> 98.611111 | AN17: =$Y$1/R17 -> 98.611111
B18: L | H18: 30023056 | N18: P002951 Box Bend | O18: =O17 -> 1 | P18: 54 | Q18: SCESBA01 | R18: =$AB$1/P18 -> 66.666667 | Y18: =$Y$1/R18 -> 15 | AB18: =$Y$1/R18 -> 15 | AE18: =$Y$1/R18 -> 15 | AH18: =$Y$1/R18 -> 15 | AK18: =$Y$1/R18 -> 15 | AN18: =$Y$1/R18 -> 15
B19: L | I19: 30023057 | J19: Delete | N19: P002951 Box Press | O19: =O17 -> 1 | P19: 24 | Q19: SCESBA01 | R19: =$AB$1/P19 -> 150 | Y19: =$Y$1/R19 -> 6.6666667 | AB19: =$Y$1/R19 -> 6.6666667 | AE19: =$Y$1/R19 -> 6.6666667 | AH19: =$Y$1/R19 -> 6.6666667 | AK19: =$Y$1/R19 -> 6.6666667 | AN19: =$Y$1/R19 -> 6.6666667
B20: L | J20: 10034385 | N20: P002951 Box GP | O20: =O19 -> 1
B21: L | H21: 30023060 | N21: P002952 BBS Holder Front Left Spot | O21: =O17 -> 1 | P21: 50 | Q21: SCESGA01 | R21: =$AB$1/P21 -> 72 | Y21: =$Y$1/R21 -> 13.888889 | AB21: =$Y$1/R21 -> 13.888889 | AE21: =$Y$1/R21 -> 13.888889 | AH21: =$Y$1/R21 -> 13.888889 | AK21: =$Y$1/R21 -> 13.888889 | AN21: =$Y$1/R21 -> 13.888889
B22: L | I22: 30023059 | N22: P002952 BBS Holder Front Left Press | O22: =O19 -> 1 | P22: 12 | Q22: SCESBA01 | R22: =$AB$1/P22 -> 300 | Y22: =$Y$1/R22 -> 3.3333333 | AB22: =$Y$1/R22 -> 3.3333333 | AE22: =$Y$1/R22 -> 3.3333333 | AH22: =$Y$1/R22 -> 3.3333333 | AK22: =$Y$1/R22 -> 3.3333333 | AN22: =$Y$1/R22 -> 3.3333333
B23: L | J23: 10034386 | N23: P002952 BBS Holder Front Left GP | O23: =O20 -> 1
B24: L | I24: 30023055 | N24: P002801 BBS Holder Front Reinf Bend | O24: =O21 -> 1 | P24: 18 | Q24: SCEBEA02 | R24: =$AB$1/P24 -> 200 | Y24: =$Y$1/R24 -> 5 | AB24: =$Y$1/R24 -> 5 | AE24: =$Y$1/R24 -> 5 | AH24: =$Y$1/R24 -> 5 | AK24: =$Y$1/R24 -> 5 | AN24: =$Y$1/R24 -> 5
B25: L | J25: 30022130 | K25: Delete | N25: P002801 BBS Holder Front Reinf Laser | O25: =O24 -> 1 | P25: 13 | Q25: SCECUA04 | R25: =$AB$1/P25 -> 276.92308 | Y25: =$Y$1/R25 -> 3.6111111 | AB25: =$Y$1/R25 -> 3.6111111 | AE25: =$Y$1/R25 -> 3.6111111 | AH25: =$Y$1/R25 -> 3.6111111 | AK25: =$Y$1/R25 -> 3.6111111 | AN25: =$Y$1/R25 -> 3.6111111
B26: L | K26: 10030768 | N26: P002801 BBS Holder Front Reinf GP | O26: =O25 -> 1
B27: L | H27: 30023062 | N27: P002953 BBS Holder Front Right Spot | O27: =O19 -> 1 | P27: 50 | Q27: SCESGA01 | R27: =$AB$1/P27 -> 72 | Y27: =$Y$1/R27 -> 13.888889 | AB27: =$Y$1/R27 -> 13.888889 | AE27: =$Y$1/R27 -> 13.888889 | AH27: =$Y$1/R27 -> 13.888889 | AK27: =$Y$1/R27 -> 13.888889 | AN27: =$Y$1/R27 -> 13.888889
B28: L | I28: 30023061 | N28: P002953 BBS Holder Front Right Press | O28: =O27 -> 1 | P28: 12 | Q28: SCESBA01 | R28: =$AB$1/P28 -> 300 | Y28: =$Y$1/R28 -> 3.3333333 | AB28: =$Y$1/R28 -> 3.3333333 | AE28: =$Y$1/R28 -> 3.3333333 | AH28: =$Y$1/R28 -> 3.3333333 | AK28: =$Y$1/R28 -> 3.3333333 | AN28: =$Y$1/R28 -> 3.3333333
B29: L | J29: 10034387 | N29: P002953 BBS Holder Front Right GP | O29: =O28 -> 1
B30: L | I30: 30023055 | N30: P002801 BBS Holder Front Reinf Bend | O30: =O27 -> 1 | P30: 18 | Q30: SCEBEA02 | R30: =$AB$1/P30 -> 200 | Y30: =$Y$1/R30 -> 5 | AB30: =$Y$1/R30 -> 5 | AE30: =$Y$1/R30 -> 5 | AH30: =$Y$1/R30 -> 5 | AK30: =$Y$1/R30 -> 5 | AN30: =$Y$1/R30 -> 5
B31: L | J31: 30022130 | K31: Delete | N31: P002801 BBS Holder Front Reinf Laser | O31: =O30 -> 1 | P31: 13 | Q31: SCECUA04 | R31: =$AB$1/P31 -> 276.92308 | Y31: =$Y$1/R31 -> 3.6111111 | AB31: =$Y$1/R31 -> 3.6111111 | AE31: =$Y$1/R31 -> 3.6111111 | AH31: =$Y$1/R31 -> 3.6111111 | AK31: =$Y$1/R31 -> 3.6111111 | AN31: =$Y$1/R31 -> 3.6111111
B32: L | K32: 10030768 | N32: P002801 BBS Holder Front Reinf GP | O32: =O31 -> 1
B33: L | H33: 30023063 | N33: P002954 BBS Holder Rear Left Press | O33: =O17 -> 1 | P33: 12 | Q33: SCESBA01 | R33: =$AB$1/P33 -> 300 | Y33: =$Y$1/R33 -> 3.3333333 | AB33: =$Y$1/R33 -> 3.3333333 | AE33: =$Y$1/R33 -> 3.3333333 | AH33: =$Y$1/R33 -> 3.3333333 | AK33: =$Y$1/R33 -> 3.3333333 | AN33: =$Y$1/R33 -> 3.3333333
B34: L | I34: 10034388 | N34: P002954 BBS Holder Rear Left GP | O34: =O33 -> 1
B35: L | H35: 30023064 | N35: P002955 BBS Holder Rear Right Press | O35: =O19 -> 1 | P35: 12 | Q35: SCESBA01 | R35: =$AB$1/P35 -> 300 | Y35: =$Y$1/R35 -> 3.3333333 | AB35: =$Y$1/R35 -> 3.3333333 | AE35: =$Y$1/R35 -> 3.3333333 | AH35: =$Y$1/R35 -> 3.3333333 | AK35: =$Y$1/R35 -> 3.3333333 | AN35: =$Y$1/R35 -> 3.3333333
B36: L | I36: 10034389 | N36: P002955 BBS Holder Rear Right GP | O36: =O35 -> 1
B37: L | H37: 30023050 | N37: P002622 Locking Slide Bend | O37: =O17 -> 1 | P37: 36 | Q37: SCEBEA02 | R37: =$AB$1/P37 -> 100 | Y37: =$Y$1/R37 -> 10 | AB37: =$Y$1/R37 -> 10 | AE37: =$Y$1/R37 -> 10 | AH37: =$Y$1/R37 -> 10 | AK37: =$Y$1/R37 -> 10 | AN37: =$Y$1/R37 -> 10
B38: L | I38: 30023145 | J38: Delete | N38: P002622 Locking Slide Laser | O38: =O37 -> 1 | P38: 8 | Q38: SCECUA04 | R38: 450 | Y38: 125 | AB38: 125 | AE38: 125 | AH38: 125 | AK38: 125 | AN38: 125
B39: L | J39: 10034294 | N39: P002622 Locking Slide GP | O39: =O37 -> 1
B40: L | H40: 30023053 | N40: P002626 Cover Support Spot | O40: =O17*2 -> 2 | P40: 32 | Q40: SCESGA01 | R40: =$AB$1/P40 -> 112.5 | Y40: =$Y$1/R40 -> 8.8888889 | AB40: =$Y$1/R40 -> 8.8888889 | AE40: =$Y$1/R40 -> 8.8888889 | AH40: =$Y$1/R40 -> 8.8888889 | AK40: =$Y$1/R40 -> 8.8888889 | AN40: =$Y$1/R40 -> 8.8888889
